Fetch Table Error: 415 Unsupported Media Type: Did not attempt to load JSON data because the request Content-Type was not 'application/json'.
Fetch Table Error: Working outside of request context.

This typically means that you attempted to use functionality that needed
an active HTTP request. Consult the documentation on testing for
information about how to avoid this problem.
Exception on / [GET]
Traceback (most recent call last):
  File "/home/lfy/ypq/project_ttqakit/TextTableQAKit/TextTableQAKit/app.py", line 460, in index
    logger.info(f"Page loaded")
AttributeError: 'NoneType' object has no attribute 'info'

During handling of the above exception, another exception occurred:

Traceback (most recent call last):
  File "/home/lfy/anaconda3/envs/ypq/lib/python3.8/site-packages/flask/app.py", line 2190, in wsgi_app
    response = self.full_dispatch_request()
  File "/home/lfy/anaconda3/envs/ypq/lib/python3.8/site-packages/flask/app.py", line 1486, in full_dispatch_request
    rv = self.handle_user_exception(e)
  File "/home/lfy/anaconda3/envs/ypq/lib/python3.8/site-packages/flask/app.py", line 1484, in full_dispatch_request
    rv = self.dispatch_request()
  File "/home/lfy/anaconda3/envs/ypq/lib/python3.8/site-packages/flask/app.py", line 1469, in dispatch_request
    return self.ensure_sync(self.view_functions[rule.endpoint])(**view_args)
  File "/home/lfy/ypq/project_ttqakit/TextTableQAKit/TextTableQAKit/app.py", line 463, in index
    logger.error(f"Fetch initial Table Error: {e}")
AttributeError: 'NoneType' object has no attribute 'error'
Exception on / [GET]
Traceback (most recent call last):
  File "/home/lfy/ypq/project_ttqakit/TextTableQAKit/TextTableQAKit/app.py", line 460, in index
    logger.info(f"Page loaded")
AttributeError: 'NoneType' object has no attribute 'info'

During handling of the above exception, another exception occurred:

Traceback (most recent call last):
  File "/home/lfy/anaconda3/envs/ypq/lib/python3.8/site-packages/flask/app.py", line 2190, in wsgi_app
    response = self.full_dispatch_request()
  File "/home/lfy/anaconda3/envs/ypq/lib/python3.8/site-packages/flask/app.py", line 1486, in full_dispatch_request
    rv = self.handle_user_exception(e)
  File "/home/lfy/anaconda3/envs/ypq/lib/python3.8/site-packages/flask/app.py", line 1484, in full_dispatch_request
    rv = self.dispatch_request()
  File "/home/lfy/anaconda3/envs/ypq/lib/python3.8/site-packages/flask/app.py", line 1469, in dispatch_request
    return self.ensure_sync(self.view_functions[rule.endpoint])(**view_args)
  File "/home/lfy/ypq/project_ttqakit/TextTableQAKit/TextTableQAKit/app.py", line 463, in index
    logger.error(f"Fetch initial Table Error: {e}")
AttributeError: 'NoneType' object has no attribute 'error'
Exception on / [GET]
Traceback (most recent call last):
  File "/home/lfy/ypq/project_ttqakit/TextTableQAKit/TextTableQAKit/app.py", line 460, in index
    logger.info(f"Page loaded")
AttributeError: 'NoneType' object has no attribute 'info'

During handling of the above exception, another exception occurred:

Traceback (most recent call last):
  File "/home/lfy/anaconda3/envs/ypq/lib/python3.8/site-packages/flask/app.py", line 2190, in wsgi_app
    response = self.full_dispatch_request()
  File "/home/lfy/anaconda3/envs/ypq/lib/python3.8/site-packages/flask/app.py", line 1486, in full_dispatch_request
    rv = self.handle_user_exception(e)
  File "/home/lfy/anaconda3/envs/ypq/lib/python3.8/site-packages/flask/app.py", line 1484, in full_dispatch_request
    rv = self.dispatch_request()
  File "/home/lfy/anaconda3/envs/ypq/lib/python3.8/site-packages/flask/app.py", line 1469, in dispatch_request
    return self.ensure_sync(self.view_functions[rule.endpoint])(**view_args)
  File "/home/lfy/ypq/project_ttqakit/TextTableQAKit/TextTableQAKit/app.py", line 463, in index
    logger.error(f"Fetch initial Table Error: {e}")
AttributeError: 'NoneType' object has no attribute 'error'
Exception on / [GET]
Traceback (most recent call last):
  File "/home/lfy/ypq/project_ttqakit/TextTableQAKit/TextTableQAKit/app.py", line 460, in index
    logger.info(f"Page loaded")
AttributeError: 'NoneType' object has no attribute 'info'

During handling of the above exception, another exception occurred:

Traceback (most recent call last):
  File "/home/lfy/anaconda3/envs/ypq/lib/python3.8/site-packages/flask/app.py", line 2190, in wsgi_app
    response = self.full_dispatch_request()
  File "/home/lfy/anaconda3/envs/ypq/lib/python3.8/site-packages/flask/app.py", line 1486, in full_dispatch_request
    rv = self.handle_user_exception(e)
  File "/home/lfy/anaconda3/envs/ypq/lib/python3.8/site-packages/flask/app.py", line 1484, in full_dispatch_request
    rv = self.dispatch_request()
  File "/home/lfy/anaconda3/envs/ypq/lib/python3.8/site-packages/flask/app.py", line 1469, in dispatch_request
    return self.ensure_sync(self.view_functions[rule.endpoint])(**view_args)
  File "/home/lfy/ypq/project_ttqakit/TextTableQAKit/TextTableQAKit/app.py", line 463, in index
    logger.error(f"Fetch initial Table Error: {e}")
AttributeError: 'NoneType' object has no attribute 'error'
Exception on / [GET]
Traceback (most recent call last):
  File "/home/lfy/ypq/project_ttqakit/TextTableQAKit/TextTableQAKit/app.py", line 460, in index
    logger.info(f"Page loaded")
AttributeError: 'NoneType' object has no attribute 'info'

During handling of the above exception, another exception occurred:

Traceback (most recent call last):
  File "/home/lfy/anaconda3/envs/ypq/lib/python3.8/site-packages/flask/app.py", line 2190, in wsgi_app
    response = self.full_dispatch_request()
  File "/home/lfy/anaconda3/envs/ypq/lib/python3.8/site-packages/flask/app.py", line 1486, in full_dispatch_request
    rv = self.handle_user_exception(e)
  File "/home/lfy/anaconda3/envs/ypq/lib/python3.8/site-packages/flask/app.py", line 1484, in full_dispatch_request
    rv = self.dispatch_request()
  File "/home/lfy/anaconda3/envs/ypq/lib/python3.8/site-packages/flask/app.py", line 1469, in dispatch_request
    return self.ensure_sync(self.view_functions[rule.endpoint])(**view_args)
  File "/home/lfy/ypq/project_ttqakit/TextTableQAKit/TextTableQAKit/app.py", line 463, in index
    logger.error(f"Fetch initial Table Error: {e}")
AttributeError: 'NoneType' object has no attribute 'error'
Exception on / [GET]
Traceback (most recent call last):
  File "/home/lfy/ypq/project_ttqakit/TextTableQAKit/TextTableQAKit/app.py", line 460, in index
    logger.info(f"Page loaded")
AttributeError: 'NoneType' object has no attribute 'info'

During handling of the above exception, another exception occurred:

Traceback (most recent call last):
  File "/home/lfy/anaconda3/envs/ypq/lib/python3.8/site-packages/flask/app.py", line 2190, in wsgi_app
    response = self.full_dispatch_request()
  File "/home/lfy/anaconda3/envs/ypq/lib/python3.8/site-packages/flask/app.py", line 1486, in full_dispatch_request
    rv = self.handle_user_exception(e)
  File "/home/lfy/anaconda3/envs/ypq/lib/python3.8/site-packages/flask/app.py", line 1484, in full_dispatch_request
    rv = self.dispatch_request()
  File "/home/lfy/anaconda3/envs/ypq/lib/python3.8/site-packages/flask/app.py", line 1469, in dispatch_request
    return self.ensure_sync(self.view_functions[rule.endpoint])(**view_args)
  File "/home/lfy/ypq/project_ttqakit/TextTableQAKit/TextTableQAKit/app.py", line 463, in index
    logger.error(f"Fetch initial Table Error: {e}")
AttributeError: 'NoneType' object has no attribute 'error'
Exception on / [GET]
Traceback (most recent call last):
  File "/home/lfy/ypq/project_ttqakit/TextTableQAKit/TextTableQAKit/app.py", line 460, in index
    logger.info(f"Page loaded")
AttributeError: 'NoneType' object has no attribute 'info'

During handling of the above exception, another exception occurred:

Traceback (most recent call last):
  File "/home/lfy/anaconda3/envs/ypq/lib/python3.8/site-packages/flask/app.py", line 2190, in wsgi_app
    response = self.full_dispatch_request()
  File "/home/lfy/anaconda3/envs/ypq/lib/python3.8/site-packages/flask/app.py", line 1486, in full_dispatch_request
    rv = self.handle_user_exception(e)
  File "/home/lfy/anaconda3/envs/ypq/lib/python3.8/site-packages/flask/app.py", line 1484, in full_dispatch_request
    rv = self.dispatch_request()
  File "/home/lfy/anaconda3/envs/ypq/lib/python3.8/site-packages/flask/app.py", line 1469, in dispatch_request
    return self.ensure_sync(self.view_functions[rule.endpoint])(**view_args)
  File "/home/lfy/ypq/project_ttqakit/TextTableQAKit/TextTableQAKit/app.py", line 463, in index
    logger.error(f"Fetch initial Table Error: {e}")
AttributeError: 'NoneType' object has no attribute 'error'
Exception on / [GET]
Traceback (most recent call last):
  File "/home/lfy/ypq/project_ttqakit/TextTableQAKit/TextTableQAKit/app.py", line 460, in index
    logger.info(f"Page loaded")
AttributeError: 'NoneType' object has no attribute 'info'

During handling of the above exception, another exception occurred:

Traceback (most recent call last):
  File "/home/lfy/anaconda3/envs/ypq/lib/python3.8/site-packages/flask/app.py", line 2190, in wsgi_app
    response = self.full_dispatch_request()
  File "/home/lfy/anaconda3/envs/ypq/lib/python3.8/site-packages/flask/app.py", line 1486, in full_dispatch_request
    rv = self.handle_user_exception(e)
  File "/home/lfy/anaconda3/envs/ypq/lib/python3.8/site-packages/flask/app.py", line 1484, in full_dispatch_request
    rv = self.dispatch_request()
  File "/home/lfy/anaconda3/envs/ypq/lib/python3.8/site-packages/flask/app.py", line 1469, in dispatch_request
    return self.ensure_sync(self.view_functions[rule.endpoint])(**view_args)
  File "/home/lfy/ypq/project_ttqakit/TextTableQAKit/TextTableQAKit/app.py", line 463, in index
    logger.error(f"Fetch initial Table Error: {e}")
AttributeError: 'NoneType' object has no attribute 'error'
Exception on / [GET]
Traceback (most recent call last):
  File "/home/lfy/ypq/project_ttqakit/TextTableQAKit/TextTableQAKit/app.py", line 460, in index
    logger.info(f"Page loaded")
AttributeError: 'NoneType' object has no attribute 'info'

During handling of the above exception, another exception occurred:

Traceback (most recent call last):
  File "/home/lfy/anaconda3/envs/ypq/lib/python3.8/site-packages/flask/app.py", line 2190, in wsgi_app
    response = self.full_dispatch_request()
  File "/home/lfy/anaconda3/envs/ypq/lib/python3.8/site-packages/flask/app.py", line 1486, in full_dispatch_request
    rv = self.handle_user_exception(e)
  File "/home/lfy/anaconda3/envs/ypq/lib/python3.8/site-packages/flask/app.py", line 1484, in full_dispatch_request
    rv = self.dispatch_request()
  File "/home/lfy/anaconda3/envs/ypq/lib/python3.8/site-packages/flask/app.py", line 1469, in dispatch_request
    return self.ensure_sync(self.view_functions[rule.endpoint])(**view_args)
  File "/home/lfy/ypq/project_ttqakit/TextTableQAKit/TextTableQAKit/app.py", line 463, in index
    logger.error(f"Fetch initial Table Error: {e}")
AttributeError: 'NoneType' object has no attribute 'error'
Fetch initial Table Error: module 'utils.export' has no attribute 'export_table'
Fetch initial Table Error: module 'utils.export' has no attribute 'export_table'
Fetch initial Table Error: module 'utils.export' has no attribute 'export_table'
Fetch initial Table Error: module 'utils.export' has no attribute 'export_table'
Fetch initial Table Error: [Errno 2] No such file or directory: 'outputs/multimodalqa/gold_answer/train.txt'
Fetch initial Table Error: [Errno 2] No such file or directory: 'outputs/multimodalqa/gold_answer/train.txt'
Fetch initial Table Error: 'mmqa'
Fetch initial Table Error: 'mmqa'
Fetch initial Table Error: 'mmqa'
Fetch initial Table Error: 'mmqa'
Fetch initial Table Error: 'mmqa'
Fetch initial Table Error: 'mmqa'
Fetch initial Table Error: 'mmqa'
Exception on / [GET]
Traceback (most recent call last):
  File "/home/lfy/anaconda3/envs/ypq/lib/python3.8/site-packages/flask/app.py", line 2190, in wsgi_app
    response = self.full_dispatch_request()
  File "/home/lfy/anaconda3/envs/ypq/lib/python3.8/site-packages/flask/app.py", line 1486, in full_dispatch_request
    rv = self.handle_user_exception(e)
  File "/home/lfy/anaconda3/envs/ypq/lib/python3.8/site-packages/flask/app.py", line 1484, in full_dispatch_request
    rv = self.dispatch_request()
  File "/home/lfy/anaconda3/envs/ypq/lib/python3.8/site-packages/flask/app.py", line 1469, in dispatch_request
    return self.ensure_sync(self.view_functions[rule.endpoint])(**view_args)
  File "/home/lfy/ypq/project_ttqakit/TextTableQAKit/TextTableQAKit/app.py", line 461, in index
    data = statistics_default_table_information(dataset_name, split, table_idx, propertie_name_list)
  File "/home/lfy/ypq/project_ttqakit/TextTableQAKit/TextTableQAKit/app.py", line 109, in statistics_default_table_information
    check_data_integrity(dataset_name, split, table_idx)
  File "/home/lfy/ypq/project_ttqakit/TextTableQAKit/TextTableQAKit/app.py", line 71, in check_data_integrity
    check_dataset_in_database(dataset_name)
  File "/home/lfy/ypq/project_ttqakit/TextTableQAKit/TextTableQAKit/app.py", line 80, in check_dataset_in_database
    create_dataset(dataset_name)
  File "/home/lfy/ypq/project_ttqakit/TextTableQAKit/TextTableQAKit/app.py", line 84, in create_dataset
    dataset_obj = DATASET_CLASSES[dataset_name]()
KeyError: 'mmqa'
Exception on / [GET]
Traceback (most recent call last):
  File "/home/lfy/anaconda3/envs/ypq/lib/python3.8/site-packages/flask/app.py", line 2190, in wsgi_app
    response = self.full_dispatch_request()
  File "/home/lfy/anaconda3/envs/ypq/lib/python3.8/site-packages/flask/app.py", line 1486, in full_dispatch_request
    rv = self.handle_user_exception(e)
  File "/home/lfy/anaconda3/envs/ypq/lib/python3.8/site-packages/flask/app.py", line 1484, in full_dispatch_request
    rv = self.dispatch_request()
  File "/home/lfy/anaconda3/envs/ypq/lib/python3.8/site-packages/flask/app.py", line 1469, in dispatch_request
    return self.ensure_sync(self.view_functions[rule.endpoint])(**view_args)
  File "/home/lfy/ypq/project_ttqakit/TextTableQAKit/TextTableQAKit/app.py", line 461, in index
    data = statistics_default_table_information(dataset_name, split, table_idx, propertie_name_list)
  File "/home/lfy/ypq/project_ttqakit/TextTableQAKit/TextTableQAKit/app.py", line 109, in statistics_default_table_information
    check_data_integrity(dataset_name, split, table_idx)
  File "/home/lfy/ypq/project_ttqakit/TextTableQAKit/TextTableQAKit/app.py", line 71, in check_data_integrity
    check_dataset_in_database(dataset_name)
  File "/home/lfy/ypq/project_ttqakit/TextTableQAKit/TextTableQAKit/app.py", line 80, in check_dataset_in_database
    create_dataset(dataset_name)
  File "/home/lfy/ypq/project_ttqakit/TextTableQAKit/TextTableQAKit/app.py", line 84, in create_dataset
    dataset_obj = DATASET_CLASSES[dataset_name]()
KeyError: 'mmqa'
Exception on / [GET]
Traceback (most recent call last):
  File "/home/lfy/anaconda3/envs/ypq/lib/python3.8/site-packages/flask/app.py", line 2190, in wsgi_app
    response = self.full_dispatch_request()
  File "/home/lfy/anaconda3/envs/ypq/lib/python3.8/site-packages/flask/app.py", line 1486, in full_dispatch_request
    rv = self.handle_user_exception(e)
  File "/home/lfy/anaconda3/envs/ypq/lib/python3.8/site-packages/flask/app.py", line 1484, in full_dispatch_request
    rv = self.dispatch_request()
  File "/home/lfy/anaconda3/envs/ypq/lib/python3.8/site-packages/flask/app.py", line 1469, in dispatch_request
    return self.ensure_sync(self.view_functions[rule.endpoint])(**view_args)
  File "/home/lfy/ypq/project_ttqakit/TextTableQAKit/TextTableQAKit/app.py", line 461, in index
    data = statistics_default_table_information(dataset_name, split, table_idx, propertie_name_list)
  File "/home/lfy/ypq/project_ttqakit/TextTableQAKit/TextTableQAKit/app.py", line 109, in statistics_default_table_information
    check_data_integrity(dataset_name, split, table_idx)
  File "/home/lfy/ypq/project_ttqakit/TextTableQAKit/TextTableQAKit/app.py", line 71, in check_data_integrity
    check_dataset_in_database(dataset_name)
  File "/home/lfy/ypq/project_ttqakit/TextTableQAKit/TextTableQAKit/app.py", line 80, in check_dataset_in_database
    create_dataset(dataset_name)
  File "/home/lfy/ypq/project_ttqakit/TextTableQAKit/TextTableQAKit/app.py", line 84, in create_dataset
    dataset_obj = DATASET_CLASSES[dataset_name]()
KeyError: 'mmqa'
Exception on / [GET]
Traceback (most recent call last):
  File "/home/lfy/anaconda3/envs/ypq/lib/python3.8/site-packages/flask/app.py", line 2190, in wsgi_app
    response = self.full_dispatch_request()
  File "/home/lfy/anaconda3/envs/ypq/lib/python3.8/site-packages/flask/app.py", line 1486, in full_dispatch_request
    rv = self.handle_user_exception(e)
  File "/home/lfy/anaconda3/envs/ypq/lib/python3.8/site-packages/flask/app.py", line 1484, in full_dispatch_request
    rv = self.dispatch_request()
  File "/home/lfy/anaconda3/envs/ypq/lib/python3.8/site-packages/flask/app.py", line 1469, in dispatch_request
    return self.ensure_sync(self.view_functions[rule.endpoint])(**view_args)
  File "/home/lfy/ypq/project_ttqakit/TextTableQAKit/TextTableQAKit/app.py", line 461, in index
    data = statistics_default_table_information(dataset_name, split, table_idx, propertie_name_list)
  File "/home/lfy/ypq/project_ttqakit/TextTableQAKit/TextTableQAKit/app.py", line 109, in statistics_default_table_information
    check_data_integrity(dataset_name, split, table_idx)
  File "/home/lfy/ypq/project_ttqakit/TextTableQAKit/TextTableQAKit/app.py", line 71, in check_data_integrity
    check_dataset_in_database(dataset_name)
  File "/home/lfy/ypq/project_ttqakit/TextTableQAKit/TextTableQAKit/app.py", line 80, in check_dataset_in_database
    create_dataset(dataset_name)
  File "/home/lfy/ypq/project_ttqakit/TextTableQAKit/TextTableQAKit/app.py", line 84, in create_dataset
    dataset_obj = DATASET_CLASSES[dataset_name]()
KeyError: 'mmqa'
Fetch Table Error: 415 Unsupported Media Type: Did not attempt to load JSON data because the request Content-Type was not 'application/json'.
Download Table Error: illegal format
Get Session Error: Illegal Target
Fetch Table Error: datasets hybriqa not found
Fetch Table Error: fetch non-existent tables in session
Remove Table Error: delete non-existent tables in session
Upload Table Error: 400 Bad Request: The browser (or proxy) sent a request that this server could not understand.
Upload Table Error: 400 Bad Request: The browser (or proxy) sent a request that this server could not understand.
Download Table Error: download non-existent tables in session
Download Table Error: datasets None not found
Fetch Table Error: 415 Unsupported Media Type: Did not attempt to load JSON data because the request Content-Type was not 'application/json'.
Fetch Table Error: 415 Unsupported Media Type: Did not attempt to load JSON data because the request Content-Type was not 'application/json'.
Fetch Table Error: 415 Unsupported Media Type: Did not attempt to load JSON data because the request Content-Type was not 'application/json'.
Upload Table Error: 415 Unsupported Media Type: Did not attempt to load JSON data because the request Content-Type was not 'application/json'.
Fetch Table Error: 415 Unsupported Media Type: Did not attempt to load JSON data because the request Content-Type was not 'application/json'.
Fetch Table Error: 415 Unsupported Media Type: Did not attempt to load JSON data because the request Content-Type was not 'application/json'.
Fetch Table Error: 415 Unsupported Media Type: Did not attempt to load JSON data because the request Content-Type was not 'application/json'.
Fetch Table Error: 415 Unsupported Media Type: Did not attempt to load JSON data because the request Content-Type was not 'application/json'.
Fetch Table Error: 415 Unsupported Media Type: Did not attempt to load JSON data because the request Content-Type was not 'application/json'.
Fetch Table Error: 415 Unsupported Media Type: Did not attempt to load JSON data because the request Content-Type was not 'application/json'.
Fetch Table Error: 415 Unsupported Media Type: Did not attempt to load JSON data because the request Content-Type was not 'application/json'.
Fetch Table Error: 415 Unsupported Media Type: Did not attempt to load JSON data because the request Content-Type was not 'application/json'.
Fetch Table Error: 415 Unsupported Media Type: Did not attempt to load JSON data because the request Content-Type was not 'application/json'.
Fetch Table Error: 415 Unsupported Media Type: Did not attempt to load JSON data because the request Content-Type was not 'application/json'.
Fetch Table Error: 415 Unsupported Media Type: Did not attempt to load JSON data because the request Content-Type was not 'application/json'.
Fetch Table Error: 415 Unsupported Media Type: Did not attempt to load JSON data because the request Content-Type was not 'application/json'.
Fetch Table Error: list indices must be integers or slices, not NoneType
Fetch Table Error: list indices must be integers or slices, not NoneType
Fetch Table Error: list indices must be integers or slices, not NoneType
Fetch Table Error: list indices must be integers or slices, not NoneType
Fetch Table Error: list indices must be integers or slices, not NoneType
Fetch Table Error: list indices must be integers or slices, not NoneType
Fetch Table Error: list indices must be integers or slices, not NoneType
Fetch Table Error: list indices must be integers or slices, not NoneType
Fetch Table Error: list indices must be integers or slices, not NoneType
Fetch Table Error: list indices must be integers or slices, not NoneType
Fetch Table Error: list indices must be integers or slices, not NoneType
Fetch Table Error: list indices must be integers or slices, not NoneType
Fetch Table Error: list indices must be integers or slices, not NoneType
Fetch Table Error: list indices must be integers or slices, not NoneType
Fetch Table Error: list indices must be integers or slices, not NoneType
Fetch Table Error: list indices must be integers or slices, not NoneType
Download Table Error: 415 Unsupported Media Type: Did not attempt to load JSON data because the request Content-Type was not 'application/json'.
Download Table Error: 415 Unsupported Media Type: Did not attempt to load JSON data because the request Content-Type was not 'application/json'.
Download Table Error: split None not found
Download Table Error: split None not found
Download Table Error: split None not found
Download Table Error: split None not found
Download Table Error: split None not found
Download Table Error: split None not found
Download Table Error: split None not found
Download Table Error: 415 Unsupported Media Type: Did not attempt to load JSON data because the request Content-Type was not 'application/json'.
Download Table Error: 415 Unsupported Media Type: Did not attempt to load JSON data because the request Content-Type was not 'application/json'.
Download Table Error: 415 Unsupported Media Type: Did not attempt to load JSON data because the request Content-Type was not 'application/json'.
Download Table Error: 415 Unsupported Media Type: Did not attempt to load JSON data because the request Content-Type was not 'application/json'.
Fetch Table Error: fetch non-existent tables in session
Fetch Table Error: list index out of range
Fetch Table Error: list index out of range
Fetch Table Error: list index out of range
Fetch Table Error: list index out of range
Fetch Table Error: list index out of range
Fetch Table Error: list index out of range
Fetch Table Error: [Errno 2] No such file or directory: 'datasets/hitab/test.jsonl'
Fetch Table Error: get_all_coordinates() takes 1 positional argument but 2 were given
Fetch Table Error: [Errno 2] No such file or directory: 'outputs/hitab/gold_answer/test.txt'
Fetch Table Error: [Errno 2] No such file or directory: 'outputs/hitab/gold_answer/test.txt'
Fetch Table Error: [Errno 2] No such file or directory: 'outputs/hitab/gold_answer/test.txt'
Download Table Error: wrap_with_div() takes 1 positional argument but 2 were given
Download Table Error: local variable 'table_html' referenced before assignment
Exception on /default/download [GET]
Traceback (most recent call last):
  File "/home/lfy/anaconda3/envs/ypq/lib/python3.8/site-packages/flask/app.py", line 2190, in wsgi_app
    response = self.full_dispatch_request()
  File "/home/lfy/anaconda3/envs/ypq/lib/python3.8/site-packages/flask/app.py", line 1486, in full_dispatch_request
    rv = self.handle_user_exception(e)
  File "/home/lfy/anaconda3/envs/ypq/lib/python3.8/site-packages/flask_cors/extension.py", line 176, in wrapped_function
    return cors_after_request(app.make_response(f(*args, **kwargs)))
  File "/home/lfy/anaconda3/envs/ypq/lib/python3.8/site-packages/flask/app.py", line 1484, in full_dispatch_request
    rv = self.dispatch_request()
  File "/home/lfy/anaconda3/envs/ypq/lib/python3.8/site-packages/flask/app.py", line 1469, in dispatch_request
    return self.ensure_sync(self.view_functions[rule.endpoint])(**view_args)
  File "/home/lfy/ypq/project_ttqakit/TextTableQAKit/TextTableQAKit/app.py", line 434, in download_default_table
    return download_table(format, table_data, include_props, f"{dataset_name}_{split}_{table_idx}")
  File "/home/lfy/ypq/project_ttqakit/TextTableQAKit/TextTableQAKit/app.py", line 375, in download_table
    content = export.table_to_html(table_data, None, include_props, "export", merge=True)
  File "/home/lfy/ypq/project_ttqakit/TextTableQAKit/TextTableQAKit/utils/export.py", line 84, in table_to_html
    combine_html = lxml.etree.tostring(lxml.html.fromstring(meta_html.render()), encoding="unicode", pretty_print=True)+table_html
UnboundLocalError: local variable 'table_html' referenced before assignment
Fetch Table Error: 415 Unsupported Media Type: Did not attempt to load JSON data because the request Content-Type was not 'application/json'.
Download Table Error: 415 Unsupported Media Type: Did not attempt to load JSON data because the request Content-Type was not 'application/json'.
Download Table Error: 415 Unsupported Media Type: Did not attempt to load JSON data because the request Content-Type was not 'application/json'.
Download Table Error: 415 Unsupported Media Type: Did not attempt to load JSON data because the request Content-Type was not 'application/json'.
Download Table Error: 415 Unsupported Media Type: Did not attempt to load JSON data because the request Content-Type was not 'application/json'.
Download Table Error: 415 Unsupported Media Type: Did not attempt to load JSON data because the request Content-Type was not 'application/json'.
Download Table Error: split None not found
Download Table Error: list indices must be integers or slices, not str
Download Table Error: list indices must be integers or slices, not str
Download Table Error: list indices must be integers or slices, not str
Download Table Error: datasets  not found
<traceback object at 0x7fd7a4789dc0>
Upload Table Error: 415 Unsupported Media Type: Did not attempt to load JSON data because the request Content-Type was not 'application/json'.
Upload Table Error: Pandas requires version '2.6.0' or newer of 'openpyxl' (version '2.4.11' currently installed).
Upload Table Error: Missing optional dependency 'xlrd'. Install xlrd >= 1.0.0 for Excel support Use pip or conda to install xlrd.
Upload Table Error: Missing optional dependency 'xlrd'. Install xlrd >= 1.0.0 for Excel support Use pip or conda to install xlrd.
Upload Table Error: Excel xlsx file; not supported
Exception on /custom/upload [GET]
Traceback (most recent call last):
  File "/home/lfy/anaconda3/envs/ypq/lib/python3.8/site-packages/flask/app.py", line 2190, in wsgi_app
    response = self.full_dispatch_request()
  File "/home/lfy/anaconda3/envs/ypq/lib/python3.8/site-packages/flask/app.py", line 1486, in full_dispatch_request
    rv = self.handle_user_exception(e)
  File "/home/lfy/anaconda3/envs/ypq/lib/python3.8/site-packages/flask_cors/extension.py", line 176, in wrapped_function
    return cors_after_request(app.make_response(f(*args, **kwargs)))
  File "/home/lfy/anaconda3/envs/ypq/lib/python3.8/site-packages/flask/app.py", line 1484, in full_dispatch_request
    rv = self.dispatch_request()
  File "/home/lfy/anaconda3/envs/ypq/lib/python3.8/site-packages/flask/app.py", line 1469, in dispatch_request
    return self.ensure_sync(self.view_functions[rule.endpoint])(**view_args)
  File "/home/lfy/ypq/project_ttqakit/TextTableQAKit/TableQAKit/app.py", line 283, in upload_custom_table
    df = pd.read_excel(file, dtype=str)
  File "/home/lfy/anaconda3/envs/ypq/lib/python3.8/site-packages/pandas/io/excel/_base.py", line 304, in read_excel
    io = ExcelFile(io, engine=engine)
  File "/home/lfy/anaconda3/envs/ypq/lib/python3.8/site-packages/pandas/io/excel/_base.py", line 824, in __init__
    self._reader = self._engines[engine](self._io)
  File "/home/lfy/anaconda3/envs/ypq/lib/python3.8/site-packages/pandas/io/excel/_xlrd.py", line 21, in __init__
    super().__init__(filepath_or_buffer)
  File "/home/lfy/anaconda3/envs/ypq/lib/python3.8/site-packages/pandas/io/excel/_base.py", line 351, in __init__
    self.book = self.load_workbook(filepath_or_buffer)
  File "/home/lfy/anaconda3/envs/ypq/lib/python3.8/site-packages/pandas/io/excel/_xlrd.py", line 34, in load_workbook
    return open_workbook(file_contents=data)
  File "/home/lfy/anaconda3/envs/ypq/lib/python3.8/site-packages/xlrd/__init__.py", line 170, in open_workbook
    raise XLRDError(FILE_FORMAT_DESCRIPTIONS[file_format]+'; not supported')
xlrd.biffh.XLRDError: Excel xlsx file; not supported
Exception on /custom/upload [GET]
Traceback (most recent call last):
  File "/home/lfy/anaconda3/envs/ypq/lib/python3.8/site-packages/flask/app.py", line 2190, in wsgi_app
    response = self.full_dispatch_request()
  File "/home/lfy/anaconda3/envs/ypq/lib/python3.8/site-packages/flask/app.py", line 1486, in full_dispatch_request
    rv = self.handle_user_exception(e)
  File "/home/lfy/anaconda3/envs/ypq/lib/python3.8/site-packages/flask_cors/extension.py", line 176, in wrapped_function
    return cors_after_request(app.make_response(f(*args, **kwargs)))
  File "/home/lfy/anaconda3/envs/ypq/lib/python3.8/site-packages/flask/app.py", line 1484, in full_dispatch_request
    rv = self.dispatch_request()
  File "/home/lfy/anaconda3/envs/ypq/lib/python3.8/site-packages/flask/app.py", line 1469, in dispatch_request
    return self.ensure_sync(self.view_functions[rule.endpoint])(**view_args)
  File "/home/lfy/ypq/project_ttqakit/TextTableQAKit/TableQAKit/app.py", line 283, in upload_custom_table
    df = pd.read_excel(file, dtype=str)
  File "/home/lfy/anaconda3/envs/ypq/lib/python3.8/site-packages/pandas/io/excel/_base.py", line 304, in read_excel
    io = ExcelFile(io, engine=engine)
  File "/home/lfy/anaconda3/envs/ypq/lib/python3.8/site-packages/pandas/io/excel/_base.py", line 824, in __init__
    self._reader = self._engines[engine](self._io)
  File "/home/lfy/anaconda3/envs/ypq/lib/python3.8/site-packages/pandas/io/excel/_xlrd.py", line 21, in __init__
    super().__init__(filepath_or_buffer)
  File "/home/lfy/anaconda3/envs/ypq/lib/python3.8/site-packages/pandas/io/excel/_base.py", line 351, in __init__
    self.book = self.load_workbook(filepath_or_buffer)
  File "/home/lfy/anaconda3/envs/ypq/lib/python3.8/site-packages/pandas/io/excel/_xlrd.py", line 34, in load_workbook
    return open_workbook(file_contents=data)
  File "/home/lfy/anaconda3/envs/ypq/lib/python3.8/site-packages/xlrd/__init__.py", line 170, in open_workbook
    raise XLRDError(FILE_FORMAT_DESCRIPTIONS[file_format]+'; not supported')
xlrd.biffh.XLRDError: Excel xlsx file; not supported
Exception on /custom/upload [GET]
Traceback (most recent call last):
  File "/home/lfy/anaconda3/envs/ypq/lib/python3.8/site-packages/flask/app.py", line 2190, in wsgi_app
    response = self.full_dispatch_request()
  File "/home/lfy/anaconda3/envs/ypq/lib/python3.8/site-packages/flask/app.py", line 1486, in full_dispatch_request
    rv = self.handle_user_exception(e)
  File "/home/lfy/anaconda3/envs/ypq/lib/python3.8/site-packages/flask_cors/extension.py", line 176, in wrapped_function
    return cors_after_request(app.make_response(f(*args, **kwargs)))
  File "/home/lfy/anaconda3/envs/ypq/lib/python3.8/site-packages/flask/app.py", line 1484, in full_dispatch_request
    rv = self.dispatch_request()
  File "/home/lfy/anaconda3/envs/ypq/lib/python3.8/site-packages/flask/app.py", line 1469, in dispatch_request
    return self.ensure_sync(self.view_functions[rule.endpoint])(**view_args)
  File "/home/lfy/ypq/project_ttqakit/TextTableQAKit/TableQAKit/app.py", line 283, in upload_custom_table
    df = pd.read_excel(file, dtype=str)
  File "/home/lfy/anaconda3/envs/ypq/lib/python3.8/site-packages/pandas/io/excel/_base.py", line 304, in read_excel
    io = ExcelFile(io, engine=engine)
  File "/home/lfy/anaconda3/envs/ypq/lib/python3.8/site-packages/pandas/io/excel/_base.py", line 824, in __init__
    self._reader = self._engines[engine](self._io)
  File "/home/lfy/anaconda3/envs/ypq/lib/python3.8/site-packages/pandas/io/excel/_xlrd.py", line 21, in __init__
    super().__init__(filepath_or_buffer)
  File "/home/lfy/anaconda3/envs/ypq/lib/python3.8/site-packages/pandas/io/excel/_base.py", line 351, in __init__
    self.book = self.load_workbook(filepath_or_buffer)
  File "/home/lfy/anaconda3/envs/ypq/lib/python3.8/site-packages/pandas/io/excel/_xlrd.py", line 34, in load_workbook
    return open_workbook(file_contents=data)
  File "/home/lfy/anaconda3/envs/ypq/lib/python3.8/site-packages/xlrd/__init__.py", line 170, in open_workbook
    raise XLRDError(FILE_FORMAT_DESCRIPTIONS[file_format]+'; not supported')
xlrd.biffh.XLRDError: Excel xlsx file; not supported
Exception on /custom/upload [GET]
Traceback (most recent call last):
  File "/home/lfy/anaconda3/envs/ypq/lib/python3.8/site-packages/flask/app.py", line 2190, in wsgi_app
    response = self.full_dispatch_request()
  File "/home/lfy/anaconda3/envs/ypq/lib/python3.8/site-packages/flask/app.py", line 1487, in full_dispatch_request
    return self.finalize_request(rv)
  File "/home/lfy/anaconda3/envs/ypq/lib/python3.8/site-packages/flask/app.py", line 1508, in finalize_request
    response = self.process_response(response)
  File "/home/lfy/anaconda3/envs/ypq/lib/python3.8/site-packages/flask/app.py", line 2005, in process_response
    self.session_interface.save_session(self, ctx.session, response)
  File "/home/lfy/anaconda3/envs/ypq/lib/python3.8/site-packages/flask/sessions.py", line 356, in save_session
    val = self.get_signing_serializer(app).dumps(dict(session))  # type: ignore
  File "/home/lfy/anaconda3/envs/ypq/lib/python3.8/site-packages/itsdangerous/serializer.py", line 207, in dumps
    payload = want_bytes(self.dump_payload(obj))
  File "/home/lfy/anaconda3/envs/ypq/lib/python3.8/site-packages/itsdangerous/url_safe.py", line 53, in dump_payload
    json = super().dump_payload(obj)
  File "/home/lfy/anaconda3/envs/ypq/lib/python3.8/site-packages/itsdangerous/serializer.py", line 169, in dump_payload
    return want_bytes(self.serializer.dumps(obj, **self.serializer_kwargs))
  File "/home/lfy/anaconda3/envs/ypq/lib/python3.8/site-packages/flask/json/tag.py", line 310, in dumps
    return dumps(self.tag(value), separators=(",", ":"))
  File "/home/lfy/anaconda3/envs/ypq/lib/python3.8/site-packages/flask/json/__init__.py", line 41, in dumps
    return current_app.json.dumps(obj, **kwargs)
  File "/home/lfy/anaconda3/envs/ypq/lib/python3.8/site-packages/flask/json/provider.py", line 180, in dumps
    return json.dumps(obj, **kwargs)
  File "/home/lfy/anaconda3/envs/ypq/lib/python3.8/json/__init__.py", line 234, in dumps
    return cls(
  File "/home/lfy/anaconda3/envs/ypq/lib/python3.8/json/encoder.py", line 199, in encode
    chunks = self.iterencode(o, _one_shot=True)
  File "/home/lfy/anaconda3/envs/ypq/lib/python3.8/json/encoder.py", line 257, in iterencode
    return _iterencode(o, 0)
  File "/home/lfy/anaconda3/envs/ypq/lib/python3.8/site-packages/flask/json/provider.py", line 120, in _default
    raise TypeError(f"Object of type {type(o).__name__} is not JSON serializable")
TypeError: Object of type Table is not JSON serializable
Request finalizing failed with an error while handling an error
Traceback (most recent call last):
  File "/home/lfy/anaconda3/envs/ypq/lib/python3.8/site-packages/flask/app.py", line 2190, in wsgi_app
    response = self.full_dispatch_request()
  File "/home/lfy/anaconda3/envs/ypq/lib/python3.8/site-packages/flask/app.py", line 1487, in full_dispatch_request
    return self.finalize_request(rv)
  File "/home/lfy/anaconda3/envs/ypq/lib/python3.8/site-packages/flask/app.py", line 1508, in finalize_request
    response = self.process_response(response)
  File "/home/lfy/anaconda3/envs/ypq/lib/python3.8/site-packages/flask/app.py", line 2005, in process_response
    self.session_interface.save_session(self, ctx.session, response)
  File "/home/lfy/anaconda3/envs/ypq/lib/python3.8/site-packages/flask/sessions.py", line 356, in save_session
    val = self.get_signing_serializer(app).dumps(dict(session))  # type: ignore
  File "/home/lfy/anaconda3/envs/ypq/lib/python3.8/site-packages/itsdangerous/serializer.py", line 207, in dumps
    payload = want_bytes(self.dump_payload(obj))
  File "/home/lfy/anaconda3/envs/ypq/lib/python3.8/site-packages/itsdangerous/url_safe.py", line 53, in dump_payload
    json = super().dump_payload(obj)
  File "/home/lfy/anaconda3/envs/ypq/lib/python3.8/site-packages/itsdangerous/serializer.py", line 169, in dump_payload
    return want_bytes(self.serializer.dumps(obj, **self.serializer_kwargs))
  File "/home/lfy/anaconda3/envs/ypq/lib/python3.8/site-packages/flask/json/tag.py", line 310, in dumps
    return dumps(self.tag(value), separators=(",", ":"))
  File "/home/lfy/anaconda3/envs/ypq/lib/python3.8/site-packages/flask/json/__init__.py", line 41, in dumps
    return current_app.json.dumps(obj, **kwargs)
  File "/home/lfy/anaconda3/envs/ypq/lib/python3.8/site-packages/flask/json/provider.py", line 180, in dumps
    return json.dumps(obj, **kwargs)
  File "/home/lfy/anaconda3/envs/ypq/lib/python3.8/json/__init__.py", line 234, in dumps
    return cls(
  File "/home/lfy/anaconda3/envs/ypq/lib/python3.8/json/encoder.py", line 199, in encode
    chunks = self.iterencode(o, _one_shot=True)
  File "/home/lfy/anaconda3/envs/ypq/lib/python3.8/json/encoder.py", line 257, in iterencode
    return _iterencode(o, 0)
  File "/home/lfy/anaconda3/envs/ypq/lib/python3.8/site-packages/flask/json/provider.py", line 120, in _default
    raise TypeError(f"Object of type {type(o).__name__} is not JSON serializable")
TypeError: Object of type Table is not JSON serializable

During handling of the above exception, another exception occurred:

Traceback (most recent call last):
  File "/home/lfy/anaconda3/envs/ypq/lib/python3.8/site-packages/flask/app.py", line 1508, in finalize_request
    response = self.process_response(response)
  File "/home/lfy/anaconda3/envs/ypq/lib/python3.8/site-packages/flask/app.py", line 2005, in process_response
    self.session_interface.save_session(self, ctx.session, response)
  File "/home/lfy/anaconda3/envs/ypq/lib/python3.8/site-packages/flask/sessions.py", line 356, in save_session
    val = self.get_signing_serializer(app).dumps(dict(session))  # type: ignore
  File "/home/lfy/anaconda3/envs/ypq/lib/python3.8/site-packages/itsdangerous/serializer.py", line 207, in dumps
    payload = want_bytes(self.dump_payload(obj))
  File "/home/lfy/anaconda3/envs/ypq/lib/python3.8/site-packages/itsdangerous/url_safe.py", line 53, in dump_payload
    json = super().dump_payload(obj)
  File "/home/lfy/anaconda3/envs/ypq/lib/python3.8/site-packages/itsdangerous/serializer.py", line 169, in dump_payload
    return want_bytes(self.serializer.dumps(obj, **self.serializer_kwargs))
  File "/home/lfy/anaconda3/envs/ypq/lib/python3.8/site-packages/flask/json/tag.py", line 310, in dumps
    return dumps(self.tag(value), separators=(",", ":"))
  File "/home/lfy/anaconda3/envs/ypq/lib/python3.8/site-packages/flask/json/__init__.py", line 41, in dumps
    return current_app.json.dumps(obj, **kwargs)
  File "/home/lfy/anaconda3/envs/ypq/lib/python3.8/site-packages/flask/json/provider.py", line 180, in dumps
    return json.dumps(obj, **kwargs)
  File "/home/lfy/anaconda3/envs/ypq/lib/python3.8/json/__init__.py", line 234, in dumps
    return cls(
  File "/home/lfy/anaconda3/envs/ypq/lib/python3.8/json/encoder.py", line 199, in encode
    chunks = self.iterencode(o, _one_shot=True)
  File "/home/lfy/anaconda3/envs/ypq/lib/python3.8/json/encoder.py", line 257, in iterencode
    return _iterencode(o, 0)
  File "/home/lfy/anaconda3/envs/ypq/lib/python3.8/site-packages/flask/json/provider.py", line 120, in _default
    raise TypeError(f"Object of type {type(o).__name__} is not JSON serializable")
TypeError: Object of type Table is not JSON serializable
Exception on /custom/upload [GET]
Traceback (most recent call last):
  File "/home/lfy/anaconda3/envs/ypq/lib/python3.8/site-packages/flask/app.py", line 2190, in wsgi_app
    response = self.full_dispatch_request()
  File "/home/lfy/anaconda3/envs/ypq/lib/python3.8/site-packages/flask/app.py", line 1486, in full_dispatch_request
    rv = self.handle_user_exception(e)
  File "/home/lfy/anaconda3/envs/ypq/lib/python3.8/site-packages/flask_cors/extension.py", line 176, in wrapped_function
    return cors_after_request(app.make_response(f(*args, **kwargs)))
  File "/home/lfy/anaconda3/envs/ypq/lib/python3.8/site-packages/flask/app.py", line 1484, in full_dispatch_request
    rv = self.dispatch_request()
  File "/home/lfy/anaconda3/envs/ypq/lib/python3.8/site-packages/flask/app.py", line 1469, in dispatch_request
    return self.ensure_sync(self.view_functions[rule.endpoint])(**view_args)
  File "/home/lfy/ypq/project_ttqakit/TextTableQAKit/TableQAKit/app.py", line 283, in upload_custom_table
    df = pd.read_excel(file, dtype=str, engine="openpyxl")
  File "/home/lfy/anaconda3/envs/ypq/lib/python3.8/site-packages/pandas/io/excel/_base.py", line 304, in read_excel
    io = ExcelFile(io, engine=engine)
  File "/home/lfy/anaconda3/envs/ypq/lib/python3.8/site-packages/pandas/io/excel/_base.py", line 824, in __init__
    self._reader = self._engines[engine](self._io)
  File "/home/lfy/anaconda3/envs/ypq/lib/python3.8/site-packages/pandas/io/excel/_openpyxl.py", line 485, in __init__
    super().__init__(filepath_or_buffer)
  File "/home/lfy/anaconda3/envs/ypq/lib/python3.8/site-packages/pandas/io/excel/_base.py", line 351, in __init__
    self.book = self.load_workbook(filepath_or_buffer)
  File "/home/lfy/anaconda3/envs/ypq/lib/python3.8/site-packages/pandas/io/excel/_openpyxl.py", line 496, in load_workbook
    return load_workbook(
  File "/home/lfy/anaconda3/envs/ypq/lib/python3.8/site-packages/openpyxl/reader/excel.py", line 312, in load_workbook
    reader.read()
  File "/home/lfy/anaconda3/envs/ypq/lib/python3.8/site-packages/openpyxl/reader/excel.py", line 270, in read
    self.read_workbook()
  File "/home/lfy/anaconda3/envs/ypq/lib/python3.8/site-packages/openpyxl/reader/excel.py", line 150, in read_workbook
    wb_part = _find_workbook_part(self.package)
  File "/home/lfy/anaconda3/envs/ypq/lib/python3.8/site-packages/openpyxl/reader/excel.py", line 115, in _find_workbook_part
    raise IOError("File contains no valid workbook part")
OSError: File contains no valid workbook part
Exception on /custom/upload [POST]
Traceback (most recent call last):
  File "/home/lfy/anaconda3/envs/ypq/lib/python3.8/site-packages/flask/app.py", line 2190, in wsgi_app
    response = self.full_dispatch_request()
  File "/home/lfy/anaconda3/envs/ypq/lib/python3.8/site-packages/flask/app.py", line 1486, in full_dispatch_request
    rv = self.handle_user_exception(e)
  File "/home/lfy/anaconda3/envs/ypq/lib/python3.8/site-packages/flask_cors/extension.py", line 176, in wrapped_function
    return cors_after_request(app.make_response(f(*args, **kwargs)))
  File "/home/lfy/anaconda3/envs/ypq/lib/python3.8/site-packages/flask/app.py", line 1484, in full_dispatch_request
    rv = self.dispatch_request()
  File "/home/lfy/anaconda3/envs/ypq/lib/python3.8/site-packages/flask/app.py", line 1469, in dispatch_request
    return self.ensure_sync(self.view_functions[rule.endpoint])(**view_args)
  File "/home/lfy/ypq/project_ttqakit/TextTableQAKit/TableQAKit/app.py", line 283, in upload_custom_table
    df = pd.read_excel(file, dtype=str, engine="openpyxl")
  File "/home/lfy/anaconda3/envs/ypq/lib/python3.8/site-packages/pandas/io/excel/_base.py", line 304, in read_excel
    io = ExcelFile(io, engine=engine)
  File "/home/lfy/anaconda3/envs/ypq/lib/python3.8/site-packages/pandas/io/excel/_base.py", line 824, in __init__
    self._reader = self._engines[engine](self._io)
  File "/home/lfy/anaconda3/envs/ypq/lib/python3.8/site-packages/pandas/io/excel/_openpyxl.py", line 485, in __init__
    super().__init__(filepath_or_buffer)
  File "/home/lfy/anaconda3/envs/ypq/lib/python3.8/site-packages/pandas/io/excel/_base.py", line 351, in __init__
    self.book = self.load_workbook(filepath_or_buffer)
  File "/home/lfy/anaconda3/envs/ypq/lib/python3.8/site-packages/pandas/io/excel/_openpyxl.py", line 496, in load_workbook
    return load_workbook(
  File "/home/lfy/anaconda3/envs/ypq/lib/python3.8/site-packages/openpyxl/reader/excel.py", line 312, in load_workbook
    reader.read()
  File "/home/lfy/anaconda3/envs/ypq/lib/python3.8/site-packages/openpyxl/reader/excel.py", line 270, in read
    self.read_workbook()
  File "/home/lfy/anaconda3/envs/ypq/lib/python3.8/site-packages/openpyxl/reader/excel.py", line 150, in read_workbook
    wb_part = _find_workbook_part(self.package)
  File "/home/lfy/anaconda3/envs/ypq/lib/python3.8/site-packages/openpyxl/reader/excel.py", line 115, in _find_workbook_part
    raise IOError("File contains no valid workbook part")
OSError: File contains no valid workbook part
Exception on /custom/upload [POST]
Traceback (most recent call last):
  File "/home/lfy/anaconda3/envs/ypq/lib/python3.8/site-packages/flask/app.py", line 2190, in wsgi_app
    response = self.full_dispatch_request()
  File "/home/lfy/anaconda3/envs/ypq/lib/python3.8/site-packages/flask/app.py", line 1487, in full_dispatch_request
    return self.finalize_request(rv)
  File "/home/lfy/anaconda3/envs/ypq/lib/python3.8/site-packages/flask/app.py", line 1508, in finalize_request
    response = self.process_response(response)
  File "/home/lfy/anaconda3/envs/ypq/lib/python3.8/site-packages/flask/app.py", line 2005, in process_response
    self.session_interface.save_session(self, ctx.session, response)
  File "/home/lfy/anaconda3/envs/ypq/lib/python3.8/site-packages/flask/sessions.py", line 356, in save_session
    val = self.get_signing_serializer(app).dumps(dict(session))  # type: ignore
  File "/home/lfy/anaconda3/envs/ypq/lib/python3.8/site-packages/itsdangerous/serializer.py", line 207, in dumps
    payload = want_bytes(self.dump_payload(obj))
  File "/home/lfy/anaconda3/envs/ypq/lib/python3.8/site-packages/itsdangerous/url_safe.py", line 53, in dump_payload
    json = super().dump_payload(obj)
  File "/home/lfy/anaconda3/envs/ypq/lib/python3.8/site-packages/itsdangerous/serializer.py", line 169, in dump_payload
    return want_bytes(self.serializer.dumps(obj, **self.serializer_kwargs))
  File "/home/lfy/anaconda3/envs/ypq/lib/python3.8/site-packages/flask/json/tag.py", line 310, in dumps
    return dumps(self.tag(value), separators=(",", ":"))
  File "/home/lfy/anaconda3/envs/ypq/lib/python3.8/site-packages/flask/json/__init__.py", line 41, in dumps
    return current_app.json.dumps(obj, **kwargs)
  File "/home/lfy/anaconda3/envs/ypq/lib/python3.8/site-packages/flask/json/provider.py", line 180, in dumps
    return json.dumps(obj, **kwargs)
  File "/home/lfy/anaconda3/envs/ypq/lib/python3.8/json/__init__.py", line 234, in dumps
    return cls(
  File "/home/lfy/anaconda3/envs/ypq/lib/python3.8/json/encoder.py", line 199, in encode
    chunks = self.iterencode(o, _one_shot=True)
  File "/home/lfy/anaconda3/envs/ypq/lib/python3.8/json/encoder.py", line 257, in iterencode
    return _iterencode(o, 0)
  File "/home/lfy/anaconda3/envs/ypq/lib/python3.8/site-packages/flask/json/provider.py", line 120, in _default
    raise TypeError(f"Object of type {type(o).__name__} is not JSON serializable")
TypeError: Object of type Table is not JSON serializable
Request finalizing failed with an error while handling an error
Traceback (most recent call last):
  File "/home/lfy/anaconda3/envs/ypq/lib/python3.8/site-packages/flask/app.py", line 2190, in wsgi_app
    response = self.full_dispatch_request()
  File "/home/lfy/anaconda3/envs/ypq/lib/python3.8/site-packages/flask/app.py", line 1487, in full_dispatch_request
    return self.finalize_request(rv)
  File "/home/lfy/anaconda3/envs/ypq/lib/python3.8/site-packages/flask/app.py", line 1508, in finalize_request
    response = self.process_response(response)
  File "/home/lfy/anaconda3/envs/ypq/lib/python3.8/site-packages/flask/app.py", line 2005, in process_response
    self.session_interface.save_session(self, ctx.session, response)
  File "/home/lfy/anaconda3/envs/ypq/lib/python3.8/site-packages/flask/sessions.py", line 356, in save_session
    val = self.get_signing_serializer(app).dumps(dict(session))  # type: ignore
  File "/home/lfy/anaconda3/envs/ypq/lib/python3.8/site-packages/itsdangerous/serializer.py", line 207, in dumps
    payload = want_bytes(self.dump_payload(obj))
  File "/home/lfy/anaconda3/envs/ypq/lib/python3.8/site-packages/itsdangerous/url_safe.py", line 53, in dump_payload
    json = super().dump_payload(obj)
  File "/home/lfy/anaconda3/envs/ypq/lib/python3.8/site-packages/itsdangerous/serializer.py", line 169, in dump_payload
    return want_bytes(self.serializer.dumps(obj, **self.serializer_kwargs))
  File "/home/lfy/anaconda3/envs/ypq/lib/python3.8/site-packages/flask/json/tag.py", line 310, in dumps
    return dumps(self.tag(value), separators=(",", ":"))
  File "/home/lfy/anaconda3/envs/ypq/lib/python3.8/site-packages/flask/json/__init__.py", line 41, in dumps
    return current_app.json.dumps(obj, **kwargs)
  File "/home/lfy/anaconda3/envs/ypq/lib/python3.8/site-packages/flask/json/provider.py", line 180, in dumps
    return json.dumps(obj, **kwargs)
  File "/home/lfy/anaconda3/envs/ypq/lib/python3.8/json/__init__.py", line 234, in dumps
    return cls(
  File "/home/lfy/anaconda3/envs/ypq/lib/python3.8/json/encoder.py", line 199, in encode
    chunks = self.iterencode(o, _one_shot=True)
  File "/home/lfy/anaconda3/envs/ypq/lib/python3.8/json/encoder.py", line 257, in iterencode
    return _iterencode(o, 0)
  File "/home/lfy/anaconda3/envs/ypq/lib/python3.8/site-packages/flask/json/provider.py", line 120, in _default
    raise TypeError(f"Object of type {type(o).__name__} is not JSON serializable")
TypeError: Object of type Table is not JSON serializable

During handling of the above exception, another exception occurred:

Traceback (most recent call last):
  File "/home/lfy/anaconda3/envs/ypq/lib/python3.8/site-packages/flask/app.py", line 1508, in finalize_request
    response = self.process_response(response)
  File "/home/lfy/anaconda3/envs/ypq/lib/python3.8/site-packages/flask/app.py", line 2005, in process_response
    self.session_interface.save_session(self, ctx.session, response)
  File "/home/lfy/anaconda3/envs/ypq/lib/python3.8/site-packages/flask/sessions.py", line 356, in save_session
    val = self.get_signing_serializer(app).dumps(dict(session))  # type: ignore
  File "/home/lfy/anaconda3/envs/ypq/lib/python3.8/site-packages/itsdangerous/serializer.py", line 207, in dumps
    payload = want_bytes(self.dump_payload(obj))
  File "/home/lfy/anaconda3/envs/ypq/lib/python3.8/site-packages/itsdangerous/url_safe.py", line 53, in dump_payload
    json = super().dump_payload(obj)
  File "/home/lfy/anaconda3/envs/ypq/lib/python3.8/site-packages/itsdangerous/serializer.py", line 169, in dump_payload
    return want_bytes(self.serializer.dumps(obj, **self.serializer_kwargs))
  File "/home/lfy/anaconda3/envs/ypq/lib/python3.8/site-packages/flask/json/tag.py", line 310, in dumps
    return dumps(self.tag(value), separators=(",", ":"))
  File "/home/lfy/anaconda3/envs/ypq/lib/python3.8/site-packages/flask/json/__init__.py", line 41, in dumps
    return current_app.json.dumps(obj, **kwargs)
  File "/home/lfy/anaconda3/envs/ypq/lib/python3.8/site-packages/flask/json/provider.py", line 180, in dumps
    return json.dumps(obj, **kwargs)
  File "/home/lfy/anaconda3/envs/ypq/lib/python3.8/json/__init__.py", line 234, in dumps
    return cls(
  File "/home/lfy/anaconda3/envs/ypq/lib/python3.8/json/encoder.py", line 199, in encode
    chunks = self.iterencode(o, _one_shot=True)
  File "/home/lfy/anaconda3/envs/ypq/lib/python3.8/json/encoder.py", line 257, in iterencode
    return _iterencode(o, 0)
  File "/home/lfy/anaconda3/envs/ypq/lib/python3.8/site-packages/flask/json/provider.py", line 120, in _default
    raise TypeError(f"Object of type {type(o).__name__} is not JSON serializable")
TypeError: Object of type Table is not JSON serializable
Exception on /custom/upload [POST]
Traceback (most recent call last):
  File "/home/lfy/anaconda3/envs/ypq/lib/python3.8/site-packages/flask/app.py", line 2190, in wsgi_app
    response = self.full_dispatch_request()
  File "/home/lfy/anaconda3/envs/ypq/lib/python3.8/site-packages/flask/app.py", line 1487, in full_dispatch_request
    return self.finalize_request(rv)
  File "/home/lfy/anaconda3/envs/ypq/lib/python3.8/site-packages/flask/app.py", line 1508, in finalize_request
    response = self.process_response(response)
  File "/home/lfy/anaconda3/envs/ypq/lib/python3.8/site-packages/flask/app.py", line 2005, in process_response
    self.session_interface.save_session(self, ctx.session, response)
  File "/home/lfy/anaconda3/envs/ypq/lib/python3.8/site-packages/flask/sessions.py", line 356, in save_session
    val = self.get_signing_serializer(app).dumps(dict(session))  # type: ignore
  File "/home/lfy/anaconda3/envs/ypq/lib/python3.8/site-packages/itsdangerous/serializer.py", line 207, in dumps
    payload = want_bytes(self.dump_payload(obj))
  File "/home/lfy/anaconda3/envs/ypq/lib/python3.8/site-packages/itsdangerous/url_safe.py", line 53, in dump_payload
    json = super().dump_payload(obj)
  File "/home/lfy/anaconda3/envs/ypq/lib/python3.8/site-packages/itsdangerous/serializer.py", line 169, in dump_payload
    return want_bytes(self.serializer.dumps(obj, **self.serializer_kwargs))
  File "/home/lfy/anaconda3/envs/ypq/lib/python3.8/site-packages/flask/json/tag.py", line 310, in dumps
    return dumps(self.tag(value), separators=(",", ":"))
  File "/home/lfy/anaconda3/envs/ypq/lib/python3.8/site-packages/flask/json/__init__.py", line 41, in dumps
    return current_app.json.dumps(obj, **kwargs)
  File "/home/lfy/anaconda3/envs/ypq/lib/python3.8/site-packages/flask/json/provider.py", line 180, in dumps
    return json.dumps(obj, **kwargs)
  File "/home/lfy/anaconda3/envs/ypq/lib/python3.8/json/__init__.py", line 234, in dumps
    return cls(
  File "/home/lfy/anaconda3/envs/ypq/lib/python3.8/json/encoder.py", line 199, in encode
    chunks = self.iterencode(o, _one_shot=True)
  File "/home/lfy/anaconda3/envs/ypq/lib/python3.8/json/encoder.py", line 257, in iterencode
    return _iterencode(o, 0)
  File "/home/lfy/anaconda3/envs/ypq/lib/python3.8/site-packages/flask/json/provider.py", line 120, in _default
    raise TypeError(f"Object of type {type(o).__name__} is not JSON serializable")
TypeError: Object of type Table is not JSON serializable
Request finalizing failed with an error while handling an error
Traceback (most recent call last):
  File "/home/lfy/anaconda3/envs/ypq/lib/python3.8/site-packages/flask/app.py", line 2190, in wsgi_app
    response = self.full_dispatch_request()
  File "/home/lfy/anaconda3/envs/ypq/lib/python3.8/site-packages/flask/app.py", line 1487, in full_dispatch_request
    return self.finalize_request(rv)
  File "/home/lfy/anaconda3/envs/ypq/lib/python3.8/site-packages/flask/app.py", line 1508, in finalize_request
    response = self.process_response(response)
  File "/home/lfy/anaconda3/envs/ypq/lib/python3.8/site-packages/flask/app.py", line 2005, in process_response
    self.session_interface.save_session(self, ctx.session, response)
  File "/home/lfy/anaconda3/envs/ypq/lib/python3.8/site-packages/flask/sessions.py", line 356, in save_session
    val = self.get_signing_serializer(app).dumps(dict(session))  # type: ignore
  File "/home/lfy/anaconda3/envs/ypq/lib/python3.8/site-packages/itsdangerous/serializer.py", line 207, in dumps
    payload = want_bytes(self.dump_payload(obj))
  File "/home/lfy/anaconda3/envs/ypq/lib/python3.8/site-packages/itsdangerous/url_safe.py", line 53, in dump_payload
    json = super().dump_payload(obj)
  File "/home/lfy/anaconda3/envs/ypq/lib/python3.8/site-packages/itsdangerous/serializer.py", line 169, in dump_payload
    return want_bytes(self.serializer.dumps(obj, **self.serializer_kwargs))
  File "/home/lfy/anaconda3/envs/ypq/lib/python3.8/site-packages/flask/json/tag.py", line 310, in dumps
    return dumps(self.tag(value), separators=(",", ":"))
  File "/home/lfy/anaconda3/envs/ypq/lib/python3.8/site-packages/flask/json/__init__.py", line 41, in dumps
    return current_app.json.dumps(obj, **kwargs)
  File "/home/lfy/anaconda3/envs/ypq/lib/python3.8/site-packages/flask/json/provider.py", line 180, in dumps
    return json.dumps(obj, **kwargs)
  File "/home/lfy/anaconda3/envs/ypq/lib/python3.8/json/__init__.py", line 234, in dumps
    return cls(
  File "/home/lfy/anaconda3/envs/ypq/lib/python3.8/json/encoder.py", line 199, in encode
    chunks = self.iterencode(o, _one_shot=True)
  File "/home/lfy/anaconda3/envs/ypq/lib/python3.8/json/encoder.py", line 257, in iterencode
    return _iterencode(o, 0)
  File "/home/lfy/anaconda3/envs/ypq/lib/python3.8/site-packages/flask/json/provider.py", line 120, in _default
    raise TypeError(f"Object of type {type(o).__name__} is not JSON serializable")
TypeError: Object of type Table is not JSON serializable

During handling of the above exception, another exception occurred:

Traceback (most recent call last):
  File "/home/lfy/anaconda3/envs/ypq/lib/python3.8/site-packages/flask/app.py", line 1508, in finalize_request
    response = self.process_response(response)
  File "/home/lfy/anaconda3/envs/ypq/lib/python3.8/site-packages/flask/app.py", line 2005, in process_response
    self.session_interface.save_session(self, ctx.session, response)
  File "/home/lfy/anaconda3/envs/ypq/lib/python3.8/site-packages/flask/sessions.py", line 356, in save_session
    val = self.get_signing_serializer(app).dumps(dict(session))  # type: ignore
  File "/home/lfy/anaconda3/envs/ypq/lib/python3.8/site-packages/itsdangerous/serializer.py", line 207, in dumps
    payload = want_bytes(self.dump_payload(obj))
  File "/home/lfy/anaconda3/envs/ypq/lib/python3.8/site-packages/itsdangerous/url_safe.py", line 53, in dump_payload
    json = super().dump_payload(obj)
  File "/home/lfy/anaconda3/envs/ypq/lib/python3.8/site-packages/itsdangerous/serializer.py", line 169, in dump_payload
    return want_bytes(self.serializer.dumps(obj, **self.serializer_kwargs))
  File "/home/lfy/anaconda3/envs/ypq/lib/python3.8/site-packages/flask/json/tag.py", line 310, in dumps
    return dumps(self.tag(value), separators=(",", ":"))
  File "/home/lfy/anaconda3/envs/ypq/lib/python3.8/site-packages/flask/json/__init__.py", line 41, in dumps
    return current_app.json.dumps(obj, **kwargs)
  File "/home/lfy/anaconda3/envs/ypq/lib/python3.8/site-packages/flask/json/provider.py", line 180, in dumps
    return json.dumps(obj, **kwargs)
  File "/home/lfy/anaconda3/envs/ypq/lib/python3.8/json/__init__.py", line 234, in dumps
    return cls(
  File "/home/lfy/anaconda3/envs/ypq/lib/python3.8/json/encoder.py", line 199, in encode
    chunks = self.iterencode(o, _one_shot=True)
  File "/home/lfy/anaconda3/envs/ypq/lib/python3.8/json/encoder.py", line 257, in iterencode
    return _iterencode(o, 0)
  File "/home/lfy/anaconda3/envs/ypq/lib/python3.8/site-packages/flask/json/provider.py", line 120, in _default
    raise TypeError(f"Object of type {type(o).__name__} is not JSON serializable")
TypeError: Object of type Table is not JSON serializable
Exception on /custom/upload [POST]
Traceback (most recent call last):
  File "/home/lfy/anaconda3/envs/ypq/lib/python3.8/site-packages/flask/app.py", line 2190, in wsgi_app
    response = self.full_dispatch_request()
  File "/home/lfy/anaconda3/envs/ypq/lib/python3.8/site-packages/flask/app.py", line 1487, in full_dispatch_request
    return self.finalize_request(rv)
  File "/home/lfy/anaconda3/envs/ypq/lib/python3.8/site-packages/flask/app.py", line 1508, in finalize_request
    response = self.process_response(response)
  File "/home/lfy/anaconda3/envs/ypq/lib/python3.8/site-packages/flask/app.py", line 2005, in process_response
    self.session_interface.save_session(self, ctx.session, response)
  File "/home/lfy/anaconda3/envs/ypq/lib/python3.8/site-packages/flask/sessions.py", line 356, in save_session
    val = self.get_signing_serializer(app).dumps(dict(session))  # type: ignore
  File "/home/lfy/anaconda3/envs/ypq/lib/python3.8/site-packages/itsdangerous/serializer.py", line 207, in dumps
    payload = want_bytes(self.dump_payload(obj))
  File "/home/lfy/anaconda3/envs/ypq/lib/python3.8/site-packages/itsdangerous/url_safe.py", line 53, in dump_payload
    json = super().dump_payload(obj)
  File "/home/lfy/anaconda3/envs/ypq/lib/python3.8/site-packages/itsdangerous/serializer.py", line 169, in dump_payload
    return want_bytes(self.serializer.dumps(obj, **self.serializer_kwargs))
  File "/home/lfy/anaconda3/envs/ypq/lib/python3.8/site-packages/flask/json/tag.py", line 310, in dumps
    return dumps(self.tag(value), separators=(",", ":"))
  File "/home/lfy/anaconda3/envs/ypq/lib/python3.8/site-packages/flask/json/__init__.py", line 41, in dumps
    return current_app.json.dumps(obj, **kwargs)
  File "/home/lfy/anaconda3/envs/ypq/lib/python3.8/site-packages/flask/json/provider.py", line 180, in dumps
    return json.dumps(obj, **kwargs)
  File "/home/lfy/anaconda3/envs/ypq/lib/python3.8/json/__init__.py", line 234, in dumps
    return cls(
  File "/home/lfy/anaconda3/envs/ypq/lib/python3.8/json/encoder.py", line 199, in encode
    chunks = self.iterencode(o, _one_shot=True)
  File "/home/lfy/anaconda3/envs/ypq/lib/python3.8/json/encoder.py", line 257, in iterencode
    return _iterencode(o, 0)
  File "/home/lfy/anaconda3/envs/ypq/lib/python3.8/site-packages/flask/json/provider.py", line 120, in _default
    raise TypeError(f"Object of type {type(o).__name__} is not JSON serializable")
TypeError: Object of type Table is not JSON serializable
Request finalizing failed with an error while handling an error
Traceback (most recent call last):
  File "/home/lfy/anaconda3/envs/ypq/lib/python3.8/site-packages/flask/app.py", line 2190, in wsgi_app
    response = self.full_dispatch_request()
  File "/home/lfy/anaconda3/envs/ypq/lib/python3.8/site-packages/flask/app.py", line 1487, in full_dispatch_request
    return self.finalize_request(rv)
  File "/home/lfy/anaconda3/envs/ypq/lib/python3.8/site-packages/flask/app.py", line 1508, in finalize_request
    response = self.process_response(response)
  File "/home/lfy/anaconda3/envs/ypq/lib/python3.8/site-packages/flask/app.py", line 2005, in process_response
    self.session_interface.save_session(self, ctx.session, response)
  File "/home/lfy/anaconda3/envs/ypq/lib/python3.8/site-packages/flask/sessions.py", line 356, in save_session
    val = self.get_signing_serializer(app).dumps(dict(session))  # type: ignore
  File "/home/lfy/anaconda3/envs/ypq/lib/python3.8/site-packages/itsdangerous/serializer.py", line 207, in dumps
    payload = want_bytes(self.dump_payload(obj))
  File "/home/lfy/anaconda3/envs/ypq/lib/python3.8/site-packages/itsdangerous/url_safe.py", line 53, in dump_payload
    json = super().dump_payload(obj)
  File "/home/lfy/anaconda3/envs/ypq/lib/python3.8/site-packages/itsdangerous/serializer.py", line 169, in dump_payload
    return want_bytes(self.serializer.dumps(obj, **self.serializer_kwargs))
  File "/home/lfy/anaconda3/envs/ypq/lib/python3.8/site-packages/flask/json/tag.py", line 310, in dumps
    return dumps(self.tag(value), separators=(",", ":"))
  File "/home/lfy/anaconda3/envs/ypq/lib/python3.8/site-packages/flask/json/__init__.py", line 41, in dumps
    return current_app.json.dumps(obj, **kwargs)
  File "/home/lfy/anaconda3/envs/ypq/lib/python3.8/site-packages/flask/json/provider.py", line 180, in dumps
    return json.dumps(obj, **kwargs)
  File "/home/lfy/anaconda3/envs/ypq/lib/python3.8/json/__init__.py", line 234, in dumps
    return cls(
  File "/home/lfy/anaconda3/envs/ypq/lib/python3.8/json/encoder.py", line 199, in encode
    chunks = self.iterencode(o, _one_shot=True)
  File "/home/lfy/anaconda3/envs/ypq/lib/python3.8/json/encoder.py", line 257, in iterencode
    return _iterencode(o, 0)
  File "/home/lfy/anaconda3/envs/ypq/lib/python3.8/site-packages/flask/json/provider.py", line 120, in _default
    raise TypeError(f"Object of type {type(o).__name__} is not JSON serializable")
TypeError: Object of type Table is not JSON serializable

During handling of the above exception, another exception occurred:

Traceback (most recent call last):
  File "/home/lfy/anaconda3/envs/ypq/lib/python3.8/site-packages/flask/app.py", line 1508, in finalize_request
    response = self.process_response(response)
  File "/home/lfy/anaconda3/envs/ypq/lib/python3.8/site-packages/flask/app.py", line 2005, in process_response
    self.session_interface.save_session(self, ctx.session, response)
  File "/home/lfy/anaconda3/envs/ypq/lib/python3.8/site-packages/flask/sessions.py", line 356, in save_session
    val = self.get_signing_serializer(app).dumps(dict(session))  # type: ignore
  File "/home/lfy/anaconda3/envs/ypq/lib/python3.8/site-packages/itsdangerous/serializer.py", line 207, in dumps
    payload = want_bytes(self.dump_payload(obj))
  File "/home/lfy/anaconda3/envs/ypq/lib/python3.8/site-packages/itsdangerous/url_safe.py", line 53, in dump_payload
    json = super().dump_payload(obj)
  File "/home/lfy/anaconda3/envs/ypq/lib/python3.8/site-packages/itsdangerous/serializer.py", line 169, in dump_payload
    return want_bytes(self.serializer.dumps(obj, **self.serializer_kwargs))
  File "/home/lfy/anaconda3/envs/ypq/lib/python3.8/site-packages/flask/json/tag.py", line 310, in dumps
    return dumps(self.tag(value), separators=(",", ":"))
  File "/home/lfy/anaconda3/envs/ypq/lib/python3.8/site-packages/flask/json/__init__.py", line 41, in dumps
    return current_app.json.dumps(obj, **kwargs)
  File "/home/lfy/anaconda3/envs/ypq/lib/python3.8/site-packages/flask/json/provider.py", line 180, in dumps
    return json.dumps(obj, **kwargs)
  File "/home/lfy/anaconda3/envs/ypq/lib/python3.8/json/__init__.py", line 234, in dumps
    return cls(
  File "/home/lfy/anaconda3/envs/ypq/lib/python3.8/json/encoder.py", line 199, in encode
    chunks = self.iterencode(o, _one_shot=True)
  File "/home/lfy/anaconda3/envs/ypq/lib/python3.8/json/encoder.py", line 257, in iterencode
    return _iterencode(o, 0)
  File "/home/lfy/anaconda3/envs/ypq/lib/python3.8/site-packages/flask/json/provider.py", line 120, in _default
    raise TypeError(f"Object of type {type(o).__name__} is not JSON serializable")
TypeError: Object of type Table is not JSON serializable
Exception on /custom/upload [POST]
Traceback (most recent call last):
  File "/home/lfy/anaconda3/envs/ypq/lib/python3.8/site-packages/flask/app.py", line 2190, in wsgi_app
    response = self.full_dispatch_request()
  File "/home/lfy/anaconda3/envs/ypq/lib/python3.8/site-packages/flask/app.py", line 1487, in full_dispatch_request
    return self.finalize_request(rv)
  File "/home/lfy/anaconda3/envs/ypq/lib/python3.8/site-packages/flask/app.py", line 1508, in finalize_request
    response = self.process_response(response)
  File "/home/lfy/anaconda3/envs/ypq/lib/python3.8/site-packages/flask/app.py", line 2005, in process_response
    self.session_interface.save_session(self, ctx.session, response)
  File "/home/lfy/anaconda3/envs/ypq/lib/python3.8/site-packages/flask/sessions.py", line 356, in save_session
    val = self.get_signing_serializer(app).dumps(dict(session))  # type: ignore
  File "/home/lfy/anaconda3/envs/ypq/lib/python3.8/site-packages/itsdangerous/serializer.py", line 207, in dumps
    payload = want_bytes(self.dump_payload(obj))
  File "/home/lfy/anaconda3/envs/ypq/lib/python3.8/site-packages/itsdangerous/url_safe.py", line 53, in dump_payload
    json = super().dump_payload(obj)
  File "/home/lfy/anaconda3/envs/ypq/lib/python3.8/site-packages/itsdangerous/serializer.py", line 169, in dump_payload
    return want_bytes(self.serializer.dumps(obj, **self.serializer_kwargs))
  File "/home/lfy/anaconda3/envs/ypq/lib/python3.8/site-packages/flask/json/tag.py", line 310, in dumps
    return dumps(self.tag(value), separators=(",", ":"))
  File "/home/lfy/anaconda3/envs/ypq/lib/python3.8/site-packages/flask/json/__init__.py", line 41, in dumps
    return current_app.json.dumps(obj, **kwargs)
  File "/home/lfy/anaconda3/envs/ypq/lib/python3.8/site-packages/flask/json/provider.py", line 180, in dumps
    return json.dumps(obj, **kwargs)
  File "/home/lfy/anaconda3/envs/ypq/lib/python3.8/json/__init__.py", line 234, in dumps
    return cls(
  File "/home/lfy/anaconda3/envs/ypq/lib/python3.8/json/encoder.py", line 199, in encode
    chunks = self.iterencode(o, _one_shot=True)
  File "/home/lfy/anaconda3/envs/ypq/lib/python3.8/json/encoder.py", line 257, in iterencode
    return _iterencode(o, 0)
  File "/home/lfy/anaconda3/envs/ypq/lib/python3.8/site-packages/flask/json/provider.py", line 120, in _default
    raise TypeError(f"Object of type {type(o).__name__} is not JSON serializable")
TypeError: Object of type Table is not JSON serializable
Request finalizing failed with an error while handling an error
Traceback (most recent call last):
  File "/home/lfy/anaconda3/envs/ypq/lib/python3.8/site-packages/flask/app.py", line 2190, in wsgi_app
    response = self.full_dispatch_request()
  File "/home/lfy/anaconda3/envs/ypq/lib/python3.8/site-packages/flask/app.py", line 1487, in full_dispatch_request
    return self.finalize_request(rv)
  File "/home/lfy/anaconda3/envs/ypq/lib/python3.8/site-packages/flask/app.py", line 1508, in finalize_request
    response = self.process_response(response)
  File "/home/lfy/anaconda3/envs/ypq/lib/python3.8/site-packages/flask/app.py", line 2005, in process_response
    self.session_interface.save_session(self, ctx.session, response)
  File "/home/lfy/anaconda3/envs/ypq/lib/python3.8/site-packages/flask/sessions.py", line 356, in save_session
    val = self.get_signing_serializer(app).dumps(dict(session))  # type: ignore
  File "/home/lfy/anaconda3/envs/ypq/lib/python3.8/site-packages/itsdangerous/serializer.py", line 207, in dumps
    payload = want_bytes(self.dump_payload(obj))
  File "/home/lfy/anaconda3/envs/ypq/lib/python3.8/site-packages/itsdangerous/url_safe.py", line 53, in dump_payload
    json = super().dump_payload(obj)
  File "/home/lfy/anaconda3/envs/ypq/lib/python3.8/site-packages/itsdangerous/serializer.py", line 169, in dump_payload
    return want_bytes(self.serializer.dumps(obj, **self.serializer_kwargs))
  File "/home/lfy/anaconda3/envs/ypq/lib/python3.8/site-packages/flask/json/tag.py", line 310, in dumps
    return dumps(self.tag(value), separators=(",", ":"))
  File "/home/lfy/anaconda3/envs/ypq/lib/python3.8/site-packages/flask/json/__init__.py", line 41, in dumps
    return current_app.json.dumps(obj, **kwargs)
  File "/home/lfy/anaconda3/envs/ypq/lib/python3.8/site-packages/flask/json/provider.py", line 180, in dumps
    return json.dumps(obj, **kwargs)
  File "/home/lfy/anaconda3/envs/ypq/lib/python3.8/json/__init__.py", line 234, in dumps
    return cls(
  File "/home/lfy/anaconda3/envs/ypq/lib/python3.8/json/encoder.py", line 199, in encode
    chunks = self.iterencode(o, _one_shot=True)
  File "/home/lfy/anaconda3/envs/ypq/lib/python3.8/json/encoder.py", line 257, in iterencode
    return _iterencode(o, 0)
  File "/home/lfy/anaconda3/envs/ypq/lib/python3.8/site-packages/flask/json/provider.py", line 120, in _default
    raise TypeError(f"Object of type {type(o).__name__} is not JSON serializable")
TypeError: Object of type Table is not JSON serializable

During handling of the above exception, another exception occurred:

Traceback (most recent call last):
  File "/home/lfy/anaconda3/envs/ypq/lib/python3.8/site-packages/flask/app.py", line 1508, in finalize_request
    response = self.process_response(response)
  File "/home/lfy/anaconda3/envs/ypq/lib/python3.8/site-packages/flask/app.py", line 2005, in process_response
    self.session_interface.save_session(self, ctx.session, response)
  File "/home/lfy/anaconda3/envs/ypq/lib/python3.8/site-packages/flask/sessions.py", line 356, in save_session
    val = self.get_signing_serializer(app).dumps(dict(session))  # type: ignore
  File "/home/lfy/anaconda3/envs/ypq/lib/python3.8/site-packages/itsdangerous/serializer.py", line 207, in dumps
    payload = want_bytes(self.dump_payload(obj))
  File "/home/lfy/anaconda3/envs/ypq/lib/python3.8/site-packages/itsdangerous/url_safe.py", line 53, in dump_payload
    json = super().dump_payload(obj)
  File "/home/lfy/anaconda3/envs/ypq/lib/python3.8/site-packages/itsdangerous/serializer.py", line 169, in dump_payload
    return want_bytes(self.serializer.dumps(obj, **self.serializer_kwargs))
  File "/home/lfy/anaconda3/envs/ypq/lib/python3.8/site-packages/flask/json/tag.py", line 310, in dumps
    return dumps(self.tag(value), separators=(",", ":"))
  File "/home/lfy/anaconda3/envs/ypq/lib/python3.8/site-packages/flask/json/__init__.py", line 41, in dumps
    return current_app.json.dumps(obj, **kwargs)
  File "/home/lfy/anaconda3/envs/ypq/lib/python3.8/site-packages/flask/json/provider.py", line 180, in dumps
    return json.dumps(obj, **kwargs)
  File "/home/lfy/anaconda3/envs/ypq/lib/python3.8/json/__init__.py", line 234, in dumps
    return cls(
  File "/home/lfy/anaconda3/envs/ypq/lib/python3.8/json/encoder.py", line 199, in encode
    chunks = self.iterencode(o, _one_shot=True)
  File "/home/lfy/anaconda3/envs/ypq/lib/python3.8/json/encoder.py", line 257, in iterencode
    return _iterencode(o, 0)
  File "/home/lfy/anaconda3/envs/ypq/lib/python3.8/site-packages/flask/json/provider.py", line 120, in _default
    raise TypeError(f"Object of type {type(o).__name__} is not JSON serializable")
TypeError: Object of type Table is not JSON serializable
Exception on /custom/upload [POST]
Traceback (most recent call last):
  File "/home/lfy/anaconda3/envs/ypq/lib/python3.8/site-packages/flask/app.py", line 2190, in wsgi_app
    response = self.full_dispatch_request()
  File "/home/lfy/anaconda3/envs/ypq/lib/python3.8/site-packages/flask/app.py", line 1487, in full_dispatch_request
    return self.finalize_request(rv)
  File "/home/lfy/anaconda3/envs/ypq/lib/python3.8/site-packages/flask/app.py", line 1508, in finalize_request
    response = self.process_response(response)
  File "/home/lfy/anaconda3/envs/ypq/lib/python3.8/site-packages/flask/app.py", line 2005, in process_response
    self.session_interface.save_session(self, ctx.session, response)
  File "/home/lfy/anaconda3/envs/ypq/lib/python3.8/site-packages/flask/sessions.py", line 356, in save_session
    val = self.get_signing_serializer(app).dumps(dict(session))  # type: ignore
  File "/home/lfy/anaconda3/envs/ypq/lib/python3.8/site-packages/itsdangerous/serializer.py", line 207, in dumps
    payload = want_bytes(self.dump_payload(obj))
  File "/home/lfy/anaconda3/envs/ypq/lib/python3.8/site-packages/itsdangerous/url_safe.py", line 53, in dump_payload
    json = super().dump_payload(obj)
  File "/home/lfy/anaconda3/envs/ypq/lib/python3.8/site-packages/itsdangerous/serializer.py", line 169, in dump_payload
    return want_bytes(self.serializer.dumps(obj, **self.serializer_kwargs))
  File "/home/lfy/anaconda3/envs/ypq/lib/python3.8/site-packages/flask/json/tag.py", line 310, in dumps
    return dumps(self.tag(value), separators=(",", ":"))
  File "/home/lfy/anaconda3/envs/ypq/lib/python3.8/site-packages/flask/json/__init__.py", line 41, in dumps
    return current_app.json.dumps(obj, **kwargs)
  File "/home/lfy/anaconda3/envs/ypq/lib/python3.8/site-packages/flask/json/provider.py", line 180, in dumps
    return json.dumps(obj, **kwargs)
  File "/home/lfy/anaconda3/envs/ypq/lib/python3.8/json/__init__.py", line 234, in dumps
    return cls(
  File "/home/lfy/anaconda3/envs/ypq/lib/python3.8/json/encoder.py", line 199, in encode
    chunks = self.iterencode(o, _one_shot=True)
  File "/home/lfy/anaconda3/envs/ypq/lib/python3.8/json/encoder.py", line 257, in iterencode
    return _iterencode(o, 0)
  File "/home/lfy/anaconda3/envs/ypq/lib/python3.8/site-packages/flask/json/provider.py", line 120, in _default
    raise TypeError(f"Object of type {type(o).__name__} is not JSON serializable")
TypeError: Object of type Table is not JSON serializable
Request finalizing failed with an error while handling an error
Traceback (most recent call last):
  File "/home/lfy/anaconda3/envs/ypq/lib/python3.8/site-packages/flask/app.py", line 2190, in wsgi_app
    response = self.full_dispatch_request()
  File "/home/lfy/anaconda3/envs/ypq/lib/python3.8/site-packages/flask/app.py", line 1487, in full_dispatch_request
    return self.finalize_request(rv)
  File "/home/lfy/anaconda3/envs/ypq/lib/python3.8/site-packages/flask/app.py", line 1508, in finalize_request
    response = self.process_response(response)
  File "/home/lfy/anaconda3/envs/ypq/lib/python3.8/site-packages/flask/app.py", line 2005, in process_response
    self.session_interface.save_session(self, ctx.session, response)
  File "/home/lfy/anaconda3/envs/ypq/lib/python3.8/site-packages/flask/sessions.py", line 356, in save_session
    val = self.get_signing_serializer(app).dumps(dict(session))  # type: ignore
  File "/home/lfy/anaconda3/envs/ypq/lib/python3.8/site-packages/itsdangerous/serializer.py", line 207, in dumps
    payload = want_bytes(self.dump_payload(obj))
  File "/home/lfy/anaconda3/envs/ypq/lib/python3.8/site-packages/itsdangerous/url_safe.py", line 53, in dump_payload
    json = super().dump_payload(obj)
  File "/home/lfy/anaconda3/envs/ypq/lib/python3.8/site-packages/itsdangerous/serializer.py", line 169, in dump_payload
    return want_bytes(self.serializer.dumps(obj, **self.serializer_kwargs))
  File "/home/lfy/anaconda3/envs/ypq/lib/python3.8/site-packages/flask/json/tag.py", line 310, in dumps
    return dumps(self.tag(value), separators=(",", ":"))
  File "/home/lfy/anaconda3/envs/ypq/lib/python3.8/site-packages/flask/json/__init__.py", line 41, in dumps
    return current_app.json.dumps(obj, **kwargs)
  File "/home/lfy/anaconda3/envs/ypq/lib/python3.8/site-packages/flask/json/provider.py", line 180, in dumps
    return json.dumps(obj, **kwargs)
  File "/home/lfy/anaconda3/envs/ypq/lib/python3.8/json/__init__.py", line 234, in dumps
    return cls(
  File "/home/lfy/anaconda3/envs/ypq/lib/python3.8/json/encoder.py", line 199, in encode
    chunks = self.iterencode(o, _one_shot=True)
  File "/home/lfy/anaconda3/envs/ypq/lib/python3.8/json/encoder.py", line 257, in iterencode
    return _iterencode(o, 0)
  File "/home/lfy/anaconda3/envs/ypq/lib/python3.8/site-packages/flask/json/provider.py", line 120, in _default
    raise TypeError(f"Object of type {type(o).__name__} is not JSON serializable")
TypeError: Object of type Table is not JSON serializable

During handling of the above exception, another exception occurred:

Traceback (most recent call last):
  File "/home/lfy/anaconda3/envs/ypq/lib/python3.8/site-packages/flask/app.py", line 1508, in finalize_request
    response = self.process_response(response)
  File "/home/lfy/anaconda3/envs/ypq/lib/python3.8/site-packages/flask/app.py", line 2005, in process_response
    self.session_interface.save_session(self, ctx.session, response)
  File "/home/lfy/anaconda3/envs/ypq/lib/python3.8/site-packages/flask/sessions.py", line 356, in save_session
    val = self.get_signing_serializer(app).dumps(dict(session))  # type: ignore
  File "/home/lfy/anaconda3/envs/ypq/lib/python3.8/site-packages/itsdangerous/serializer.py", line 207, in dumps
    payload = want_bytes(self.dump_payload(obj))
  File "/home/lfy/anaconda3/envs/ypq/lib/python3.8/site-packages/itsdangerous/url_safe.py", line 53, in dump_payload
    json = super().dump_payload(obj)
  File "/home/lfy/anaconda3/envs/ypq/lib/python3.8/site-packages/itsdangerous/serializer.py", line 169, in dump_payload
    return want_bytes(self.serializer.dumps(obj, **self.serializer_kwargs))
  File "/home/lfy/anaconda3/envs/ypq/lib/python3.8/site-packages/flask/json/tag.py", line 310, in dumps
    return dumps(self.tag(value), separators=(",", ":"))
  File "/home/lfy/anaconda3/envs/ypq/lib/python3.8/site-packages/flask/json/__init__.py", line 41, in dumps
    return current_app.json.dumps(obj, **kwargs)
  File "/home/lfy/anaconda3/envs/ypq/lib/python3.8/site-packages/flask/json/provider.py", line 180, in dumps
    return json.dumps(obj, **kwargs)
  File "/home/lfy/anaconda3/envs/ypq/lib/python3.8/json/__init__.py", line 234, in dumps
    return cls(
  File "/home/lfy/anaconda3/envs/ypq/lib/python3.8/json/encoder.py", line 199, in encode
    chunks = self.iterencode(o, _one_shot=True)
  File "/home/lfy/anaconda3/envs/ypq/lib/python3.8/json/encoder.py", line 257, in iterencode
    return _iterencode(o, 0)
  File "/home/lfy/anaconda3/envs/ypq/lib/python3.8/site-packages/flask/json/provider.py", line 120, in _default
    raise TypeError(f"Object of type {type(o).__name__} is not JSON serializable")
TypeError: Object of type Table is not JSON serializable
Exception on /custom/upload [POST]
Traceback (most recent call last):
  File "/home/lfy/anaconda3/envs/ypq/lib/python3.8/site-packages/flask/app.py", line 2190, in wsgi_app
    response = self.full_dispatch_request()
  File "/home/lfy/anaconda3/envs/ypq/lib/python3.8/site-packages/flask/app.py", line 1487, in full_dispatch_request
    return self.finalize_request(rv)
  File "/home/lfy/anaconda3/envs/ypq/lib/python3.8/site-packages/flask/app.py", line 1508, in finalize_request
    response = self.process_response(response)
  File "/home/lfy/anaconda3/envs/ypq/lib/python3.8/site-packages/flask/app.py", line 2005, in process_response
    self.session_interface.save_session(self, ctx.session, response)
  File "/home/lfy/anaconda3/envs/ypq/lib/python3.8/site-packages/flask/sessions.py", line 356, in save_session
    val = self.get_signing_serializer(app).dumps(dict(session))  # type: ignore
  File "/home/lfy/anaconda3/envs/ypq/lib/python3.8/site-packages/itsdangerous/serializer.py", line 207, in dumps
    payload = want_bytes(self.dump_payload(obj))
  File "/home/lfy/anaconda3/envs/ypq/lib/python3.8/site-packages/itsdangerous/url_safe.py", line 53, in dump_payload
    json = super().dump_payload(obj)
  File "/home/lfy/anaconda3/envs/ypq/lib/python3.8/site-packages/itsdangerous/serializer.py", line 169, in dump_payload
    return want_bytes(self.serializer.dumps(obj, **self.serializer_kwargs))
  File "/home/lfy/anaconda3/envs/ypq/lib/python3.8/site-packages/flask/json/tag.py", line 310, in dumps
    return dumps(self.tag(value), separators=(",", ":"))
  File "/home/lfy/anaconda3/envs/ypq/lib/python3.8/site-packages/flask/json/__init__.py", line 41, in dumps
    return current_app.json.dumps(obj, **kwargs)
  File "/home/lfy/anaconda3/envs/ypq/lib/python3.8/site-packages/flask/json/provider.py", line 180, in dumps
    return json.dumps(obj, **kwargs)
  File "/home/lfy/anaconda3/envs/ypq/lib/python3.8/json/__init__.py", line 234, in dumps
    return cls(
  File "/home/lfy/anaconda3/envs/ypq/lib/python3.8/json/encoder.py", line 199, in encode
    chunks = self.iterencode(o, _one_shot=True)
  File "/home/lfy/anaconda3/envs/ypq/lib/python3.8/json/encoder.py", line 257, in iterencode
    return _iterencode(o, 0)
  File "/home/lfy/anaconda3/envs/ypq/lib/python3.8/site-packages/flask/json/provider.py", line 120, in _default
    raise TypeError(f"Object of type {type(o).__name__} is not JSON serializable")
TypeError: Object of type Table is not JSON serializable
Request finalizing failed with an error while handling an error
Traceback (most recent call last):
  File "/home/lfy/anaconda3/envs/ypq/lib/python3.8/site-packages/flask/app.py", line 2190, in wsgi_app
    response = self.full_dispatch_request()
  File "/home/lfy/anaconda3/envs/ypq/lib/python3.8/site-packages/flask/app.py", line 1487, in full_dispatch_request
    return self.finalize_request(rv)
  File "/home/lfy/anaconda3/envs/ypq/lib/python3.8/site-packages/flask/app.py", line 1508, in finalize_request
    response = self.process_response(response)
  File "/home/lfy/anaconda3/envs/ypq/lib/python3.8/site-packages/flask/app.py", line 2005, in process_response
    self.session_interface.save_session(self, ctx.session, response)
  File "/home/lfy/anaconda3/envs/ypq/lib/python3.8/site-packages/flask/sessions.py", line 356, in save_session
    val = self.get_signing_serializer(app).dumps(dict(session))  # type: ignore
  File "/home/lfy/anaconda3/envs/ypq/lib/python3.8/site-packages/itsdangerous/serializer.py", line 207, in dumps
    payload = want_bytes(self.dump_payload(obj))
  File "/home/lfy/anaconda3/envs/ypq/lib/python3.8/site-packages/itsdangerous/url_safe.py", line 53, in dump_payload
    json = super().dump_payload(obj)
  File "/home/lfy/anaconda3/envs/ypq/lib/python3.8/site-packages/itsdangerous/serializer.py", line 169, in dump_payload
    return want_bytes(self.serializer.dumps(obj, **self.serializer_kwargs))
  File "/home/lfy/anaconda3/envs/ypq/lib/python3.8/site-packages/flask/json/tag.py", line 310, in dumps
    return dumps(self.tag(value), separators=(",", ":"))
  File "/home/lfy/anaconda3/envs/ypq/lib/python3.8/site-packages/flask/json/__init__.py", line 41, in dumps
    return current_app.json.dumps(obj, **kwargs)
  File "/home/lfy/anaconda3/envs/ypq/lib/python3.8/site-packages/flask/json/provider.py", line 180, in dumps
    return json.dumps(obj, **kwargs)
  File "/home/lfy/anaconda3/envs/ypq/lib/python3.8/json/__init__.py", line 234, in dumps
    return cls(
  File "/home/lfy/anaconda3/envs/ypq/lib/python3.8/json/encoder.py", line 199, in encode
    chunks = self.iterencode(o, _one_shot=True)
  File "/home/lfy/anaconda3/envs/ypq/lib/python3.8/json/encoder.py", line 257, in iterencode
    return _iterencode(o, 0)
  File "/home/lfy/anaconda3/envs/ypq/lib/python3.8/site-packages/flask/json/provider.py", line 120, in _default
    raise TypeError(f"Object of type {type(o).__name__} is not JSON serializable")
TypeError: Object of type Table is not JSON serializable

During handling of the above exception, another exception occurred:

Traceback (most recent call last):
  File "/home/lfy/anaconda3/envs/ypq/lib/python3.8/site-packages/flask/app.py", line 1508, in finalize_request
    response = self.process_response(response)
  File "/home/lfy/anaconda3/envs/ypq/lib/python3.8/site-packages/flask/app.py", line 2005, in process_response
    self.session_interface.save_session(self, ctx.session, response)
  File "/home/lfy/anaconda3/envs/ypq/lib/python3.8/site-packages/flask/sessions.py", line 356, in save_session
    val = self.get_signing_serializer(app).dumps(dict(session))  # type: ignore
  File "/home/lfy/anaconda3/envs/ypq/lib/python3.8/site-packages/itsdangerous/serializer.py", line 207, in dumps
    payload = want_bytes(self.dump_payload(obj))
  File "/home/lfy/anaconda3/envs/ypq/lib/python3.8/site-packages/itsdangerous/url_safe.py", line 53, in dump_payload
    json = super().dump_payload(obj)
  File "/home/lfy/anaconda3/envs/ypq/lib/python3.8/site-packages/itsdangerous/serializer.py", line 169, in dump_payload
    return want_bytes(self.serializer.dumps(obj, **self.serializer_kwargs))
  File "/home/lfy/anaconda3/envs/ypq/lib/python3.8/site-packages/flask/json/tag.py", line 310, in dumps
    return dumps(self.tag(value), separators=(",", ":"))
  File "/home/lfy/anaconda3/envs/ypq/lib/python3.8/site-packages/flask/json/__init__.py", line 41, in dumps
    return current_app.json.dumps(obj, **kwargs)
  File "/home/lfy/anaconda3/envs/ypq/lib/python3.8/site-packages/flask/json/provider.py", line 180, in dumps
    return json.dumps(obj, **kwargs)
  File "/home/lfy/anaconda3/envs/ypq/lib/python3.8/json/__init__.py", line 234, in dumps
    return cls(
  File "/home/lfy/anaconda3/envs/ypq/lib/python3.8/json/encoder.py", line 199, in encode
    chunks = self.iterencode(o, _one_shot=True)
  File "/home/lfy/anaconda3/envs/ypq/lib/python3.8/json/encoder.py", line 257, in iterencode
    return _iterencode(o, 0)
  File "/home/lfy/anaconda3/envs/ypq/lib/python3.8/site-packages/flask/json/provider.py", line 120, in _default
    raise TypeError(f"Object of type {type(o).__name__} is not JSON serializable")
TypeError: Object of type Table is not JSON serializable
Exception on /custom/upload [POST]
Traceback (most recent call last):
  File "/home/lfy/anaconda3/envs/ypq/lib/python3.8/site-packages/flask/app.py", line 2190, in wsgi_app
    response = self.full_dispatch_request()
  File "/home/lfy/anaconda3/envs/ypq/lib/python3.8/site-packages/flask/app.py", line 1487, in full_dispatch_request
    return self.finalize_request(rv)
  File "/home/lfy/anaconda3/envs/ypq/lib/python3.8/site-packages/flask/app.py", line 1508, in finalize_request
    response = self.process_response(response)
  File "/home/lfy/anaconda3/envs/ypq/lib/python3.8/site-packages/flask/app.py", line 2005, in process_response
    self.session_interface.save_session(self, ctx.session, response)
  File "/home/lfy/anaconda3/envs/ypq/lib/python3.8/site-packages/flask/sessions.py", line 356, in save_session
    val = self.get_signing_serializer(app).dumps(dict(session))  # type: ignore
  File "/home/lfy/anaconda3/envs/ypq/lib/python3.8/site-packages/itsdangerous/serializer.py", line 207, in dumps
    payload = want_bytes(self.dump_payload(obj))
  File "/home/lfy/anaconda3/envs/ypq/lib/python3.8/site-packages/itsdangerous/url_safe.py", line 53, in dump_payload
    json = super().dump_payload(obj)
  File "/home/lfy/anaconda3/envs/ypq/lib/python3.8/site-packages/itsdangerous/serializer.py", line 169, in dump_payload
    return want_bytes(self.serializer.dumps(obj, **self.serializer_kwargs))
  File "/home/lfy/anaconda3/envs/ypq/lib/python3.8/site-packages/flask/json/tag.py", line 310, in dumps
    return dumps(self.tag(value), separators=(",", ":"))
  File "/home/lfy/anaconda3/envs/ypq/lib/python3.8/site-packages/flask/json/__init__.py", line 41, in dumps
    return current_app.json.dumps(obj, **kwargs)
  File "/home/lfy/anaconda3/envs/ypq/lib/python3.8/site-packages/flask/json/provider.py", line 180, in dumps
    return json.dumps(obj, **kwargs)
  File "/home/lfy/anaconda3/envs/ypq/lib/python3.8/json/__init__.py", line 234, in dumps
    return cls(
  File "/home/lfy/anaconda3/envs/ypq/lib/python3.8/json/encoder.py", line 199, in encode
    chunks = self.iterencode(o, _one_shot=True)
  File "/home/lfy/anaconda3/envs/ypq/lib/python3.8/json/encoder.py", line 257, in iterencode
    return _iterencode(o, 0)
  File "/home/lfy/anaconda3/envs/ypq/lib/python3.8/site-packages/flask/json/provider.py", line 120, in _default
    raise TypeError(f"Object of type {type(o).__name__} is not JSON serializable")
TypeError: Object of type Table is not JSON serializable
Request finalizing failed with an error while handling an error
Traceback (most recent call last):
  File "/home/lfy/anaconda3/envs/ypq/lib/python3.8/site-packages/flask/app.py", line 2190, in wsgi_app
    response = self.full_dispatch_request()
  File "/home/lfy/anaconda3/envs/ypq/lib/python3.8/site-packages/flask/app.py", line 1487, in full_dispatch_request
    return self.finalize_request(rv)
  File "/home/lfy/anaconda3/envs/ypq/lib/python3.8/site-packages/flask/app.py", line 1508, in finalize_request
    response = self.process_response(response)
  File "/home/lfy/anaconda3/envs/ypq/lib/python3.8/site-packages/flask/app.py", line 2005, in process_response
    self.session_interface.save_session(self, ctx.session, response)
  File "/home/lfy/anaconda3/envs/ypq/lib/python3.8/site-packages/flask/sessions.py", line 356, in save_session
    val = self.get_signing_serializer(app).dumps(dict(session))  # type: ignore
  File "/home/lfy/anaconda3/envs/ypq/lib/python3.8/site-packages/itsdangerous/serializer.py", line 207, in dumps
    payload = want_bytes(self.dump_payload(obj))
  File "/home/lfy/anaconda3/envs/ypq/lib/python3.8/site-packages/itsdangerous/url_safe.py", line 53, in dump_payload
    json = super().dump_payload(obj)
  File "/home/lfy/anaconda3/envs/ypq/lib/python3.8/site-packages/itsdangerous/serializer.py", line 169, in dump_payload
    return want_bytes(self.serializer.dumps(obj, **self.serializer_kwargs))
  File "/home/lfy/anaconda3/envs/ypq/lib/python3.8/site-packages/flask/json/tag.py", line 310, in dumps
    return dumps(self.tag(value), separators=(",", ":"))
  File "/home/lfy/anaconda3/envs/ypq/lib/python3.8/site-packages/flask/json/__init__.py", line 41, in dumps
    return current_app.json.dumps(obj, **kwargs)
  File "/home/lfy/anaconda3/envs/ypq/lib/python3.8/site-packages/flask/json/provider.py", line 180, in dumps
    return json.dumps(obj, **kwargs)
  File "/home/lfy/anaconda3/envs/ypq/lib/python3.8/json/__init__.py", line 234, in dumps
    return cls(
  File "/home/lfy/anaconda3/envs/ypq/lib/python3.8/json/encoder.py", line 199, in encode
    chunks = self.iterencode(o, _one_shot=True)
  File "/home/lfy/anaconda3/envs/ypq/lib/python3.8/json/encoder.py", line 257, in iterencode
    return _iterencode(o, 0)
  File "/home/lfy/anaconda3/envs/ypq/lib/python3.8/site-packages/flask/json/provider.py", line 120, in _default
    raise TypeError(f"Object of type {type(o).__name__} is not JSON serializable")
TypeError: Object of type Table is not JSON serializable

During handling of the above exception, another exception occurred:

Traceback (most recent call last):
  File "/home/lfy/anaconda3/envs/ypq/lib/python3.8/site-packages/flask/app.py", line 1508, in finalize_request
    response = self.process_response(response)
  File "/home/lfy/anaconda3/envs/ypq/lib/python3.8/site-packages/flask/app.py", line 2005, in process_response
    self.session_interface.save_session(self, ctx.session, response)
  File "/home/lfy/anaconda3/envs/ypq/lib/python3.8/site-packages/flask/sessions.py", line 356, in save_session
    val = self.get_signing_serializer(app).dumps(dict(session))  # type: ignore
  File "/home/lfy/anaconda3/envs/ypq/lib/python3.8/site-packages/itsdangerous/serializer.py", line 207, in dumps
    payload = want_bytes(self.dump_payload(obj))
  File "/home/lfy/anaconda3/envs/ypq/lib/python3.8/site-packages/itsdangerous/url_safe.py", line 53, in dump_payload
    json = super().dump_payload(obj)
  File "/home/lfy/anaconda3/envs/ypq/lib/python3.8/site-packages/itsdangerous/serializer.py", line 169, in dump_payload
    return want_bytes(self.serializer.dumps(obj, **self.serializer_kwargs))
  File "/home/lfy/anaconda3/envs/ypq/lib/python3.8/site-packages/flask/json/tag.py", line 310, in dumps
    return dumps(self.tag(value), separators=(",", ":"))
  File "/home/lfy/anaconda3/envs/ypq/lib/python3.8/site-packages/flask/json/__init__.py", line 41, in dumps
    return current_app.json.dumps(obj, **kwargs)
  File "/home/lfy/anaconda3/envs/ypq/lib/python3.8/site-packages/flask/json/provider.py", line 180, in dumps
    return json.dumps(obj, **kwargs)
  File "/home/lfy/anaconda3/envs/ypq/lib/python3.8/json/__init__.py", line 234, in dumps
    return cls(
  File "/home/lfy/anaconda3/envs/ypq/lib/python3.8/json/encoder.py", line 199, in encode
    chunks = self.iterencode(o, _one_shot=True)
  File "/home/lfy/anaconda3/envs/ypq/lib/python3.8/json/encoder.py", line 257, in iterencode
    return _iterencode(o, 0)
  File "/home/lfy/anaconda3/envs/ypq/lib/python3.8/site-packages/flask/json/provider.py", line 120, in _default
    raise TypeError(f"Object of type {type(o).__name__} is not JSON serializable")
TypeError: Object of type Table is not JSON serializable
Exception on /custom/upload [POST]
Traceback (most recent call last):
  File "/home/lfy/anaconda3/envs/ypq/lib/python3.8/site-packages/flask/app.py", line 2190, in wsgi_app
    response = self.full_dispatch_request()
  File "/home/lfy/anaconda3/envs/ypq/lib/python3.8/site-packages/flask/app.py", line 1487, in full_dispatch_request
    return self.finalize_request(rv)
  File "/home/lfy/anaconda3/envs/ypq/lib/python3.8/site-packages/flask/app.py", line 1506, in finalize_request
    response = self.make_response(rv)
  File "/home/lfy/anaconda3/envs/ypq/lib/python3.8/site-packages/flask/app.py", line 1837, in make_response
    raise TypeError(
TypeError: The view function did not return a valid response. The return type must be a string, dict, list, tuple with headers or status, Response instance, or WSGI callable, but it was a int.
Request finalizing failed with an error while handling an error
Traceback (most recent call last):
  File "/home/lfy/anaconda3/envs/ypq/lib/python3.8/site-packages/flask/app.py", line 2190, in wsgi_app
    response = self.full_dispatch_request()
  File "/home/lfy/anaconda3/envs/ypq/lib/python3.8/site-packages/flask/app.py", line 1487, in full_dispatch_request
    return self.finalize_request(rv)
  File "/home/lfy/anaconda3/envs/ypq/lib/python3.8/site-packages/flask/app.py", line 1506, in finalize_request
    response = self.make_response(rv)
  File "/home/lfy/anaconda3/envs/ypq/lib/python3.8/site-packages/flask/app.py", line 1837, in make_response
    raise TypeError(
TypeError: The view function did not return a valid response. The return type must be a string, dict, list, tuple with headers or status, Response instance, or WSGI callable, but it was a int.

During handling of the above exception, another exception occurred:

Traceback (most recent call last):
  File "/home/lfy/anaconda3/envs/ypq/lib/python3.8/site-packages/flask/app.py", line 1508, in finalize_request
    response = self.process_response(response)
  File "/home/lfy/anaconda3/envs/ypq/lib/python3.8/site-packages/flask/app.py", line 2005, in process_response
    self.session_interface.save_session(self, ctx.session, response)
  File "/home/lfy/anaconda3/envs/ypq/lib/python3.8/site-packages/flask/sessions.py", line 356, in save_session
    val = self.get_signing_serializer(app).dumps(dict(session))  # type: ignore
  File "/home/lfy/anaconda3/envs/ypq/lib/python3.8/site-packages/itsdangerous/serializer.py", line 207, in dumps
    payload = want_bytes(self.dump_payload(obj))
  File "/home/lfy/anaconda3/envs/ypq/lib/python3.8/site-packages/itsdangerous/url_safe.py", line 53, in dump_payload
    json = super().dump_payload(obj)
  File "/home/lfy/anaconda3/envs/ypq/lib/python3.8/site-packages/itsdangerous/serializer.py", line 169, in dump_payload
    return want_bytes(self.serializer.dumps(obj, **self.serializer_kwargs))
  File "/home/lfy/anaconda3/envs/ypq/lib/python3.8/site-packages/flask/json/tag.py", line 310, in dumps
    return dumps(self.tag(value), separators=(",", ":"))
  File "/home/lfy/anaconda3/envs/ypq/lib/python3.8/site-packages/flask/json/__init__.py", line 41, in dumps
    return current_app.json.dumps(obj, **kwargs)
  File "/home/lfy/anaconda3/envs/ypq/lib/python3.8/site-packages/flask/json/provider.py", line 180, in dumps
    return json.dumps(obj, **kwargs)
  File "/home/lfy/anaconda3/envs/ypq/lib/python3.8/json/__init__.py", line 234, in dumps
    return cls(
  File "/home/lfy/anaconda3/envs/ypq/lib/python3.8/json/encoder.py", line 199, in encode
    chunks = self.iterencode(o, _one_shot=True)
  File "/home/lfy/anaconda3/envs/ypq/lib/python3.8/json/encoder.py", line 257, in iterencode
    return _iterencode(o, 0)
  File "/home/lfy/anaconda3/envs/ypq/lib/python3.8/site-packages/flask/json/provider.py", line 120, in _default
    raise TypeError(f"Object of type {type(o).__name__} is not JSON serializable")
TypeError: Object of type Table is not JSON serializable
Exception on /custom/upload [POST]
Traceback (most recent call last):
  File "/home/lfy/anaconda3/envs/ypq/lib/python3.8/site-packages/flask/app.py", line 2190, in wsgi_app
    response = self.full_dispatch_request()
  File "/home/lfy/anaconda3/envs/ypq/lib/python3.8/site-packages/flask/app.py", line 1487, in full_dispatch_request
    return self.finalize_request(rv)
  File "/home/lfy/anaconda3/envs/ypq/lib/python3.8/site-packages/flask/app.py", line 1508, in finalize_request
    response = self.process_response(response)
  File "/home/lfy/anaconda3/envs/ypq/lib/python3.8/site-packages/flask/app.py", line 2005, in process_response
    self.session_interface.save_session(self, ctx.session, response)
  File "/home/lfy/anaconda3/envs/ypq/lib/python3.8/site-packages/flask/sessions.py", line 356, in save_session
    val = self.get_signing_serializer(app).dumps(dict(session))  # type: ignore
  File "/home/lfy/anaconda3/envs/ypq/lib/python3.8/site-packages/itsdangerous/serializer.py", line 207, in dumps
    payload = want_bytes(self.dump_payload(obj))
  File "/home/lfy/anaconda3/envs/ypq/lib/python3.8/site-packages/itsdangerous/url_safe.py", line 53, in dump_payload
    json = super().dump_payload(obj)
  File "/home/lfy/anaconda3/envs/ypq/lib/python3.8/site-packages/itsdangerous/serializer.py", line 169, in dump_payload
    return want_bytes(self.serializer.dumps(obj, **self.serializer_kwargs))
  File "/home/lfy/anaconda3/envs/ypq/lib/python3.8/site-packages/flask/json/tag.py", line 310, in dumps
    return dumps(self.tag(value), separators=(",", ":"))
  File "/home/lfy/anaconda3/envs/ypq/lib/python3.8/site-packages/flask/json/__init__.py", line 41, in dumps
    return current_app.json.dumps(obj, **kwargs)
  File "/home/lfy/anaconda3/envs/ypq/lib/python3.8/site-packages/flask/json/provider.py", line 180, in dumps
    return json.dumps(obj, **kwargs)
  File "/home/lfy/anaconda3/envs/ypq/lib/python3.8/json/__init__.py", line 234, in dumps
    return cls(
  File "/home/lfy/anaconda3/envs/ypq/lib/python3.8/json/encoder.py", line 199, in encode
    chunks = self.iterencode(o, _one_shot=True)
  File "/home/lfy/anaconda3/envs/ypq/lib/python3.8/json/encoder.py", line 257, in iterencode
    return _iterencode(o, 0)
  File "/home/lfy/anaconda3/envs/ypq/lib/python3.8/site-packages/flask/json/provider.py", line 120, in _default
    raise TypeError(f"Object of type {type(o).__name__} is not JSON serializable")
TypeError: Object of type Table is not JSON serializable
Request finalizing failed with an error while handling an error
Traceback (most recent call last):
  File "/home/lfy/anaconda3/envs/ypq/lib/python3.8/site-packages/flask/app.py", line 2190, in wsgi_app
    response = self.full_dispatch_request()
  File "/home/lfy/anaconda3/envs/ypq/lib/python3.8/site-packages/flask/app.py", line 1487, in full_dispatch_request
    return self.finalize_request(rv)
  File "/home/lfy/anaconda3/envs/ypq/lib/python3.8/site-packages/flask/app.py", line 1508, in finalize_request
    response = self.process_response(response)
  File "/home/lfy/anaconda3/envs/ypq/lib/python3.8/site-packages/flask/app.py", line 2005, in process_response
    self.session_interface.save_session(self, ctx.session, response)
  File "/home/lfy/anaconda3/envs/ypq/lib/python3.8/site-packages/flask/sessions.py", line 356, in save_session
    val = self.get_signing_serializer(app).dumps(dict(session))  # type: ignore
  File "/home/lfy/anaconda3/envs/ypq/lib/python3.8/site-packages/itsdangerous/serializer.py", line 207, in dumps
    payload = want_bytes(self.dump_payload(obj))
  File "/home/lfy/anaconda3/envs/ypq/lib/python3.8/site-packages/itsdangerous/url_safe.py", line 53, in dump_payload
    json = super().dump_payload(obj)
  File "/home/lfy/anaconda3/envs/ypq/lib/python3.8/site-packages/itsdangerous/serializer.py", line 169, in dump_payload
    return want_bytes(self.serializer.dumps(obj, **self.serializer_kwargs))
  File "/home/lfy/anaconda3/envs/ypq/lib/python3.8/site-packages/flask/json/tag.py", line 310, in dumps
    return dumps(self.tag(value), separators=(",", ":"))
  File "/home/lfy/anaconda3/envs/ypq/lib/python3.8/site-packages/flask/json/__init__.py", line 41, in dumps
    return current_app.json.dumps(obj, **kwargs)
  File "/home/lfy/anaconda3/envs/ypq/lib/python3.8/site-packages/flask/json/provider.py", line 180, in dumps
    return json.dumps(obj, **kwargs)
  File "/home/lfy/anaconda3/envs/ypq/lib/python3.8/json/__init__.py", line 234, in dumps
    return cls(
  File "/home/lfy/anaconda3/envs/ypq/lib/python3.8/json/encoder.py", line 199, in encode
    chunks = self.iterencode(o, _one_shot=True)
  File "/home/lfy/anaconda3/envs/ypq/lib/python3.8/json/encoder.py", line 257, in iterencode
    return _iterencode(o, 0)
  File "/home/lfy/anaconda3/envs/ypq/lib/python3.8/site-packages/flask/json/provider.py", line 120, in _default
    raise TypeError(f"Object of type {type(o).__name__} is not JSON serializable")
TypeError: Object of type Table is not JSON serializable

During handling of the above exception, another exception occurred:

Traceback (most recent call last):
  File "/home/lfy/anaconda3/envs/ypq/lib/python3.8/site-packages/flask/app.py", line 1508, in finalize_request
    response = self.process_response(response)
  File "/home/lfy/anaconda3/envs/ypq/lib/python3.8/site-packages/flask/app.py", line 2005, in process_response
    self.session_interface.save_session(self, ctx.session, response)
  File "/home/lfy/anaconda3/envs/ypq/lib/python3.8/site-packages/flask/sessions.py", line 356, in save_session
    val = self.get_signing_serializer(app).dumps(dict(session))  # type: ignore
  File "/home/lfy/anaconda3/envs/ypq/lib/python3.8/site-packages/itsdangerous/serializer.py", line 207, in dumps
    payload = want_bytes(self.dump_payload(obj))
  File "/home/lfy/anaconda3/envs/ypq/lib/python3.8/site-packages/itsdangerous/url_safe.py", line 53, in dump_payload
    json = super().dump_payload(obj)
  File "/home/lfy/anaconda3/envs/ypq/lib/python3.8/site-packages/itsdangerous/serializer.py", line 169, in dump_payload
    return want_bytes(self.serializer.dumps(obj, **self.serializer_kwargs))
  File "/home/lfy/anaconda3/envs/ypq/lib/python3.8/site-packages/flask/json/tag.py", line 310, in dumps
    return dumps(self.tag(value), separators=(",", ":"))
  File "/home/lfy/anaconda3/envs/ypq/lib/python3.8/site-packages/flask/json/__init__.py", line 41, in dumps
    return current_app.json.dumps(obj, **kwargs)
  File "/home/lfy/anaconda3/envs/ypq/lib/python3.8/site-packages/flask/json/provider.py", line 180, in dumps
    return json.dumps(obj, **kwargs)
  File "/home/lfy/anaconda3/envs/ypq/lib/python3.8/json/__init__.py", line 234, in dumps
    return cls(
  File "/home/lfy/anaconda3/envs/ypq/lib/python3.8/json/encoder.py", line 199, in encode
    chunks = self.iterencode(o, _one_shot=True)
  File "/home/lfy/anaconda3/envs/ypq/lib/python3.8/json/encoder.py", line 257, in iterencode
    return _iterencode(o, 0)
  File "/home/lfy/anaconda3/envs/ypq/lib/python3.8/site-packages/flask/json/provider.py", line 120, in _default
    raise TypeError(f"Object of type {type(o).__name__} is not JSON serializable")
TypeError: Object of type Table is not JSON serializable
Fetch Table Error: list index out of range
Pipeline Error: can only concatenate str (not "NoneType") to str
Fetch Table Error: split eval not found
Pipeline Error: 
Fetch Table Error: list indices must be integers or slices, not NoneType
Upload Table Error: 400 Bad Request: The browser (or proxy) sent a request that this server could not understand.
Upload Table Error: 400 Bad Request: The browser (or proxy) sent a request that this server could not understand.
Upload Table Error: 400 Bad Request: The browser (or proxy) sent a request that this server could not understand.
Upload Table Error: add duplicate names to tables in session
Upload Table Error: add duplicate names to tables in session
Get Session Error: 415 Unsupported Media Type: Did not attempt to load JSON data because the request Content-Type was not 'application/json'.
Upload Table Error: Unsupported file format. Only .xls and .xlsx are supported.
Fetch Table Error: 400 Bad Request: The browser (or proxy) sent a request that this server could not understand.
Download Table Error: download non-existent tables in session
Upload Table Error: add duplicate names to tables in session
Upload Table Error: add duplicate names to tables in session
Upload Table Error: add duplicate names to tables in session
Upload Table Error: add duplicate names to tables in session
Upload Table Error: add duplicate names to tables in session
Upload Table Error: add duplicate names to tables in session
Upload Table Error: add duplicate names to tables in session
Upload Table Error: add duplicate names to tables in session
